ERROR 2025-06-07 00:51:37,524 exception 16020 6052 Invalid HTTP_HOST header: '127.0.0.1:8000'. You may need to add '127.0.0.1' to ALLOWED_HOSTS.
Traceback (most recent call last):
  File "C:\Users\Gonzalo\Desktop\punto_fitness\env\Lib\site-packages\django\core\handlers\exception.py", line 55, in inner
    response = get_response(request)
  File "C:\Users\Gonzalo\Desktop\punto_fitness\env\Lib\site-packages\django\utils\deprecation.py", line 119, in __call__
    response = self.process_request(request)
  File "C:\Users\Gonzalo\Desktop\punto_fitness\env\Lib\site-packages\django\middleware\common.py", line 48, in process_request
    host = request.get_host()
  File "C:\Users\Gonzalo\Desktop\punto_fitness\env\Lib\site-packages\django\http\request.py", line 191, in get_host
    raise DisallowedHost(msg)
django.core.exceptions.DisallowedHost: Invalid HTTP_HOST header: '127.0.0.1:8000'. You may need to add '127.0.0.1' to ALLOWED_HOSTS.
ERROR 2025-06-07 00:51:37,790 exception 16020 18568 Invalid HTTP_HOST header: '127.0.0.1:8000'. You may need to add '127.0.0.1' to ALLOWED_HOSTS.
Traceback (most recent call last):
  File "C:\Users\Gonzalo\Desktop\punto_fitness\env\Lib\site-packages\django\core\handlers\exception.py", line 55, in inner
    response = get_response(request)
  File "C:\Users\Gonzalo\Desktop\punto_fitness\env\Lib\site-packages\django\utils\deprecation.py", line 119, in __call__
    response = self.process_request(request)
  File "C:\Users\Gonzalo\Desktop\punto_fitness\env\Lib\site-packages\django\middleware\common.py", line 48, in process_request
    host = request.get_host()
  File "C:\Users\Gonzalo\Desktop\punto_fitness\env\Lib\site-packages\django\http\request.py", line 191, in get_host
    raise DisallowedHost(msg)
django.core.exceptions.DisallowedHost: Invalid HTTP_HOST header: '127.0.0.1:8000'. You may need to add '127.0.0.1' to ALLOWED_HOSTS.
ERROR 2025-06-07 01:48:12,831 log 14428 16528 Internal Server Error: /cambiar-rol-admin/
Traceback (most recent call last):
  File "C:\Users\Gonzalo\Desktop\punto_fitness\env\Lib\site-packages\django\core\handlers\exception.py", line 55, in inner
    response = get_response(request)
  File "C:\Users\Gonzalo\Desktop\punto_fitness\env\Lib\site-packages\django\core\handlers\base.py", line 197, in _get_response
    response = wrapped_callback(request, *callback_args, **callback_kwargs)
  File "C:\Users\Gonzalo\Desktop\punto_fitness\env\Lib\site-packages\django\views\decorators\csrf.py", line 65, in _view_wrapper
    return view_func(request, *args, **kwargs)
  File "C:\Users\Gonzalo\Desktop\punto_fitness\punto_fitness\punto_app\views.py", line 927, in cambiar_rol_admin
    admin, created = Administrador.objects.get_or_create(
                     ~~~~~~~~~~~~~~~~~~~~~~~~~~~~~~~~~~~^
        id_cliente=cliente,
        ^^^^^^^^^^^^^^^^^^^
        defaults={'nivel_acceso': 'admin', 'establecimiento_id': establecimiento_id}
        ^^^^^^^^^^^^^^^^^^^^^^^^^^^^^^^^^^^^^^^^^^^^^^^^^^^^^^^^^^^^^^^^^^^^^^^^^^^^
    )
    ^
  File "C:\Users\Gonzalo\Desktop\punto_fitness\env\Lib\site-packages\django\db\models\manager.py", line 87, in manager_method
    return getattr(self.get_queryset(), name)(*args, **kwargs)
           ~~~~~~~~~~~~~~~~~~~~~~~~~~~~~~~~~~^^^^^^^^^^^^^^^^^
  File "C:\Users\Gonzalo\Desktop\punto_fitness\env\Lib\site-packages\django\db\models\query.py", line 946, in get_or_create
    return self.get(**kwargs), False
           ~~~~~~~~^^^^^^^^^^
  File "C:\Users\Gonzalo\Desktop\punto_fitness\env\Lib\site-packages\django\db\models\query.py", line 619, in get
    clone = self._chain() if self.query.combinator else self.filter(*args, **kwargs)
                                                        ~~~~~~~~~~~^^^^^^^^^^^^^^^^^
  File "C:\Users\Gonzalo\Desktop\punto_fitness\env\Lib\site-packages\django\db\models\query.py", line 1493, in filter
    return self._filter_or_exclude(False, args, kwargs)
           ~~~~~~~~~~~~~~~~~~~~~~~^^^^^^^^^^^^^^^^^^^^^
  File "C:\Users\Gonzalo\Desktop\punto_fitness\env\Lib\site-packages\django\db\models\query.py", line 1511, in _filter_or_exclude
    clone._filter_or_exclude_inplace(negate, args, kwargs)
    ~~~~~~~~~~~~~~~~~~~~~~~~~~~~~~~~^^^^^^^^^^^^^^^^^^^^^^
  File "C:\Users\Gonzalo\Desktop\punto_fitness\env\Lib\site-packages\django\db\models\query.py", line 1518, in _filter_or_exclude_inplace
    self._query.add_q(Q(*args, **kwargs))
    ~~~~~~~~~~~~~~~~~^^^^^^^^^^^^^^^^^^^^
  File "C:\Users\Gonzalo\Desktop\punto_fitness\env\Lib\site-packages\django\db\models\sql\query.py", line 1646, in add_q
    clause, _ = self._add_q(q_object, can_reuse)
                ~~~~~~~~~~~^^^^^^^^^^^^^^^^^^^^^
  File "C:\Users\Gonzalo\Desktop\punto_fitness\env\Lib\site-packages\django\db\models\sql\query.py", line 1678, in _add_q
    child_clause, needed_inner = self.build_filter(
                                 ~~~~~~~~~~~~~~~~~^
        child,
        ^^^^^^
    ...<7 lines>...
        update_join_types=update_join_types,
        ^^^^^^^^^^^^^^^^^^^^^^^^^^^^^^^^^^^^
    )
    ^
  File "C:\Users\Gonzalo\Desktop\punto_fitness\env\Lib\site-packages\django\db\models\sql\query.py", line 1526, in build_filter
    lookups, parts, reffed_expression = self.solve_lookup_type(arg, summarize)
                                        ~~~~~~~~~~~~~~~~~~~~~~^^^^^^^^^^^^^^^^
  File "C:\Users\Gonzalo\Desktop\punto_fitness\env\Lib\site-packages\django\db\models\sql\query.py", line 1333, in solve_lookup_type
    _, field, _, lookup_parts = self.names_to_path(lookup_splitted, self.get_meta())
                                ~~~~~~~~~~~~~~~~~~^^^^^^^^^^^^^^^^^^^^^^^^^^^^^^^^^^
  File "C:\Users\Gonzalo\Desktop\punto_fitness\env\Lib\site-packages\django\db\models\sql\query.py", line 1805, in names_to_path
    raise FieldError(
    ...<2 lines>...
    )
django.core.exceptions.FieldError: Cannot resolve keyword 'id_cliente' into field. Choices are: cliente, cliente_id, establecimiento, establecimiento_id, id, nivel_acceso
ERROR 2025-06-07 01:48:12,842 basehttp 14428 16528 "POST /cambiar-rol-admin/ HTTP/1.1" 500 129361
ERROR 2025-06-07 02:29:50,808 log 16576 7836 Internal Server Error: /admin-dashboard/
Traceback (most recent call last):
  File "C:\Users\Gonzalo\Desktop\punto_fitness\env\Lib\site-packages\django\core\handlers\exception.py", line 55, in inner
    response = get_response(request)
  File "C:\Users\Gonzalo\Desktop\punto_fitness\env\Lib\site-packages\django\core\handlers\base.py", line 197, in _get_response
    response = wrapped_callback(request, *callback_args, **callback_kwargs)
  File "C:\Users\Gonzalo\Desktop\punto_fitness\punto_fitness\punto_app\views.py", line 183, in pagina_admin
    return render(request, 'punto_app/pagina_admin.html')
  File "C:\Users\Gonzalo\Desktop\punto_fitness\env\Lib\site-packages\django\shortcuts.py", line 25, in render
    content = loader.render_to_string(template_name, context, request, using=using)
  File "C:\Users\Gonzalo\Desktop\punto_fitness\env\Lib\site-packages\django\template\loader.py", line 61, in render_to_string
    template = get_template(template_name, using=using)
  File "C:\Users\Gonzalo\Desktop\punto_fitness\env\Lib\site-packages\django\template\loader.py", line 19, in get_template
    raise TemplateDoesNotExist(template_name, chain=chain)
django.template.exceptions.TemplateDoesNotExist: punto_app/pagina_admin.html
ERROR 2025-06-07 02:29:50,812 basehttp 16576 7836 "GET /admin-dashboard/ HTTP/1.1" 500 85663
ERROR 2025-06-07 02:51:50,931 log 9572 7700 Internal Server Error: /admin-dashboard/
Traceback (most recent call last):
  File "C:\Users\Gonzalo\Desktop\punto_fitness\env\Lib\site-packages\django\core\handlers\exception.py", line 55, in inner
    response = get_response(request)
  File "C:\Users\Gonzalo\Desktop\punto_fitness\env\Lib\site-packages\django\core\handlers\base.py", line 197, in _get_response
    response = wrapped_callback(request, *callback_args, **callback_kwargs)
  File "C:\Users\Gonzalo\Desktop\punto_fitness\punto_fitness\punto_app\views.py", line 168, in pagina_admin
    return render(request, 'punto_app/admin_dashboard.html')
  File "C:\Users\Gonzalo\Desktop\punto_fitness\env\Lib\site-packages\django\shortcuts.py", line 25, in render
    content = loader.render_to_string(template_name, context, request, using=using)
  File "C:\Users\Gonzalo\Desktop\punto_fitness\env\Lib\site-packages\django\template\loader.py", line 62, in render_to_string
    return template.render(context, request)
           ~~~~~~~~~~~~~~~^^^^^^^^^^^^^^^^^^
  File "C:\Users\Gonzalo\Desktop\punto_fitness\env\Lib\site-packages\django\template\backends\django.py", line 107, in render
    return self.template.render(context)
           ~~~~~~~~~~~~~~~~~~~~^^^^^^^^^
  File "C:\Users\Gonzalo\Desktop\punto_fitness\env\Lib\site-packages\django\template\base.py", line 169, in render
    with context.bind_template(self):
         ~~~~~~~~~~~~~~~~~~~~~^^^^^^
  File "C:\Python313\Lib\contextlib.py", line 141, in __enter__
    return next(self.gen)
  File "C:\Users\Gonzalo\Desktop\punto_fitness\env\Lib\site-packages\django\template\context.py", line 259, in bind_template
    context = processor(self.request)
  File "C:\Users\Gonzalo\Desktop\punto_fitness\punto_fitness\punto_app\context_processors.py", line 12, in user_info
    cliente_data['cliente_email'] = cliente.correo
                                    ^^^^^^^^^^^^^^
AttributeError: 'Cliente' object has no attribute 'correo'
ERROR 2025-06-07 02:51:50,937 basehttp 9572 7700 "GET /admin-dashboard/ HTTP/1.1" 500 101986
