ERROR 2025-06-07 00:51:37,524 exception 16020 6052 Invalid HTTP_HOST header: '127.0.0.1:8000'. You may need to add '127.0.0.1' to ALLOWED_HOSTS.
Traceback (most recent call last):
  File "C:\Users\Gonzalo\Desktop\punto_fitness\env\Lib\site-packages\django\core\handlers\exception.py", line 55, in inner
    response = get_response(request)
  File "C:\Users\Gonzalo\Desktop\punto_fitness\env\Lib\site-packages\django\utils\deprecation.py", line 119, in __call__
    response = self.process_request(request)
  File "C:\Users\Gonzalo\Desktop\punto_fitness\env\Lib\site-packages\django\middleware\common.py", line 48, in process_request
    host = request.get_host()
  File "C:\Users\Gonzalo\Desktop\punto_fitness\env\Lib\site-packages\django\http\request.py", line 191, in get_host
    raise DisallowedHost(msg)
django.core.exceptions.DisallowedHost: Invalid HTTP_HOST header: '127.0.0.1:8000'. You may need to add '127.0.0.1' to ALLOWED_HOSTS.
ERROR 2025-06-07 00:51:37,790 exception 16020 18568 Invalid HTTP_HOST header: '127.0.0.1:8000'. You may need to add '127.0.0.1' to ALLOWED_HOSTS.
Traceback (most recent call last):
  File "C:\Users\Gonzalo\Desktop\punto_fitness\env\Lib\site-packages\django\core\handlers\exception.py", line 55, in inner
    response = get_response(request)
  File "C:\Users\Gonzalo\Desktop\punto_fitness\env\Lib\site-packages\django\utils\deprecation.py", line 119, in __call__
    response = self.process_request(request)
  File "C:\Users\Gonzalo\Desktop\punto_fitness\env\Lib\site-packages\django\middleware\common.py", line 48, in process_request
    host = request.get_host()
  File "C:\Users\Gonzalo\Desktop\punto_fitness\env\Lib\site-packages\django\http\request.py", line 191, in get_host
    raise DisallowedHost(msg)
django.core.exceptions.DisallowedHost: Invalid HTTP_HOST header: '127.0.0.1:8000'. You may need to add '127.0.0.1' to ALLOWED_HOSTS.
ERROR 2025-06-07 01:48:12,831 log 14428 16528 Internal Server Error: /cambiar-rol-admin/
Traceback (most recent call last):
  File "C:\Users\Gonzalo\Desktop\punto_fitness\env\Lib\site-packages\django\core\handlers\exception.py", line 55, in inner
    response = get_response(request)
  File "C:\Users\Gonzalo\Desktop\punto_fitness\env\Lib\site-packages\django\core\handlers\base.py", line 197, in _get_response
    response = wrapped_callback(request, *callback_args, **callback_kwargs)
  File "C:\Users\Gonzalo\Desktop\punto_fitness\env\Lib\site-packages\django\views\decorators\csrf.py", line 65, in _view_wrapper
    return view_func(request, *args, **kwargs)
  File "C:\Users\Gonzalo\Desktop\punto_fitness\punto_fitness\punto_app\views.py", line 927, in cambiar_rol_admin
    admin, created = Administrador.objects.get_or_create(
                     ~~~~~~~~~~~~~~~~~~~~~~~~~~~~~~~~~~~^
        id_cliente=cliente,
        ^^^^^^^^^^^^^^^^^^^
        defaults={'nivel_acceso': 'admin', 'establecimiento_id': establecimiento_id}
        ^^^^^^^^^^^^^^^^^^^^^^^^^^^^^^^^^^^^^^^^^^^^^^^^^^^^^^^^^^^^^^^^^^^^^^^^^^^^
    )
    ^
  File "C:\Users\Gonzalo\Desktop\punto_fitness\env\Lib\site-packages\django\db\models\manager.py", line 87, in manager_method
    return getattr(self.get_queryset(), name)(*args, **kwargs)
           ~~~~~~~~~~~~~~~~~~~~~~~~~~~~~~~~~~^^^^^^^^^^^^^^^^^
  File "C:\Users\Gonzalo\Desktop\punto_fitness\env\Lib\site-packages\django\db\models\query.py", line 946, in get_or_create
    return self.get(**kwargs), False
           ~~~~~~~~^^^^^^^^^^
  File "C:\Users\Gonzalo\Desktop\punto_fitness\env\Lib\site-packages\django\db\models\query.py", line 619, in get
    clone = self._chain() if self.query.combinator else self.filter(*args, **kwargs)
                                                        ~~~~~~~~~~~^^^^^^^^^^^^^^^^^
  File "C:\Users\Gonzalo\Desktop\punto_fitness\env\Lib\site-packages\django\db\models\query.py", line 1493, in filter
    return self._filter_or_exclude(False, args, kwargs)
           ~~~~~~~~~~~~~~~~~~~~~~~^^^^^^^^^^^^^^^^^^^^^
  File "C:\Users\Gonzalo\Desktop\punto_fitness\env\Lib\site-packages\django\db\models\query.py", line 1511, in _filter_or_exclude
    clone._filter_or_exclude_inplace(negate, args, kwargs)
    ~~~~~~~~~~~~~~~~~~~~~~~~~~~~~~~~^^^^^^^^^^^^^^^^^^^^^^
  File "C:\Users\Gonzalo\Desktop\punto_fitness\env\Lib\site-packages\django\db\models\query.py", line 1518, in _filter_or_exclude_inplace
    self._query.add_q(Q(*args, **kwargs))
    ~~~~~~~~~~~~~~~~~^^^^^^^^^^^^^^^^^^^^
  File "C:\Users\Gonzalo\Desktop\punto_fitness\env\Lib\site-packages\django\db\models\sql\query.py", line 1646, in add_q
    clause, _ = self._add_q(q_object, can_reuse)
                ~~~~~~~~~~~^^^^^^^^^^^^^^^^^^^^^
  File "C:\Users\Gonzalo\Desktop\punto_fitness\env\Lib\site-packages\django\db\models\sql\query.py", line 1678, in _add_q
    child_clause, needed_inner = self.build_filter(
                                 ~~~~~~~~~~~~~~~~~^
        child,
        ^^^^^^
    ...<7 lines>...
        update_join_types=update_join_types,
        ^^^^^^^^^^^^^^^^^^^^^^^^^^^^^^^^^^^^
    )
    ^
  File "C:\Users\Gonzalo\Desktop\punto_fitness\env\Lib\site-packages\django\db\models\sql\query.py", line 1526, in build_filter
    lookups, parts, reffed_expression = self.solve_lookup_type(arg, summarize)
                                        ~~~~~~~~~~~~~~~~~~~~~~^^^^^^^^^^^^^^^^
  File "C:\Users\Gonzalo\Desktop\punto_fitness\env\Lib\site-packages\django\db\models\sql\query.py", line 1333, in solve_lookup_type
    _, field, _, lookup_parts = self.names_to_path(lookup_splitted, self.get_meta())
                                ~~~~~~~~~~~~~~~~~~^^^^^^^^^^^^^^^^^^^^^^^^^^^^^^^^^^
  File "C:\Users\Gonzalo\Desktop\punto_fitness\env\Lib\site-packages\django\db\models\sql\query.py", line 1805, in names_to_path
    raise FieldError(
    ...<2 lines>...
    )
django.core.exceptions.FieldError: Cannot resolve keyword 'id_cliente' into field. Choices are: cliente, cliente_id, establecimiento, establecimiento_id, id, nivel_acceso
ERROR 2025-06-07 01:48:12,842 basehttp 14428 16528 "POST /cambiar-rol-admin/ HTTP/1.1" 500 129361
ERROR 2025-06-07 02:29:50,808 log 16576 7836 Internal Server Error: /admin-dashboard/
Traceback (most recent call last):
  File "C:\Users\Gonzalo\Desktop\punto_fitness\env\Lib\site-packages\django\core\handlers\exception.py", line 55, in inner
    response = get_response(request)
  File "C:\Users\Gonzalo\Desktop\punto_fitness\env\Lib\site-packages\django\core\handlers\base.py", line 197, in _get_response
    response = wrapped_callback(request, *callback_args, **callback_kwargs)
  File "C:\Users\Gonzalo\Desktop\punto_fitness\punto_fitness\punto_app\views.py", line 183, in pagina_admin
    return render(request, 'punto_app/pagina_admin.html')
  File "C:\Users\Gonzalo\Desktop\punto_fitness\env\Lib\site-packages\django\shortcuts.py", line 25, in render
    content = loader.render_to_string(template_name, context, request, using=using)
  File "C:\Users\Gonzalo\Desktop\punto_fitness\env\Lib\site-packages\django\template\loader.py", line 61, in render_to_string
    template = get_template(template_name, using=using)
  File "C:\Users\Gonzalo\Desktop\punto_fitness\env\Lib\site-packages\django\template\loader.py", line 19, in get_template
    raise TemplateDoesNotExist(template_name, chain=chain)
django.template.exceptions.TemplateDoesNotExist: punto_app/pagina_admin.html
ERROR 2025-06-07 02:29:50,812 basehttp 16576 7836 "GET /admin-dashboard/ HTTP/1.1" 500 85663
ERROR 2025-06-07 02:51:50,931 log 9572 7700 Internal Server Error: /admin-dashboard/
Traceback (most recent call last):
  File "C:\Users\Gonzalo\Desktop\punto_fitness\env\Lib\site-packages\django\core\handlers\exception.py", line 55, in inner
    response = get_response(request)
  File "C:\Users\Gonzalo\Desktop\punto_fitness\env\Lib\site-packages\django\core\handlers\base.py", line 197, in _get_response
    response = wrapped_callback(request, *callback_args, **callback_kwargs)
  File "C:\Users\Gonzalo\Desktop\punto_fitness\punto_fitness\punto_app\views.py", line 168, in pagina_admin
    return render(request, 'punto_app/admin_dashboard.html')
  File "C:\Users\Gonzalo\Desktop\punto_fitness\env\Lib\site-packages\django\shortcuts.py", line 25, in render
    content = loader.render_to_string(template_name, context, request, using=using)
  File "C:\Users\Gonzalo\Desktop\punto_fitness\env\Lib\site-packages\django\template\loader.py", line 62, in render_to_string
    return template.render(context, request)
           ~~~~~~~~~~~~~~~^^^^^^^^^^^^^^^^^^
  File "C:\Users\Gonzalo\Desktop\punto_fitness\env\Lib\site-packages\django\template\backends\django.py", line 107, in render
    return self.template.render(context)
           ~~~~~~~~~~~~~~~~~~~~^^^^^^^^^
  File "C:\Users\Gonzalo\Desktop\punto_fitness\env\Lib\site-packages\django\template\base.py", line 169, in render
    with context.bind_template(self):
         ~~~~~~~~~~~~~~~~~~~~~^^^^^^
  File "C:\Python313\Lib\contextlib.py", line 141, in __enter__
    return next(self.gen)
  File "C:\Users\Gonzalo\Desktop\punto_fitness\env\Lib\site-packages\django\template\context.py", line 259, in bind_template
    context = processor(self.request)
  File "C:\Users\Gonzalo\Desktop\punto_fitness\punto_fitness\punto_app\context_processors.py", line 12, in user_info
    cliente_data['cliente_email'] = cliente.correo
                                    ^^^^^^^^^^^^^^
AttributeError: 'Cliente' object has no attribute 'correo'
ERROR 2025-06-07 02:51:50,937 basehttp 9572 7700 "GET /admin-dashboard/ HTTP/1.1" 500 101986
ERROR 2025-06-09 01:29:49,342 log 1188 3048 Internal Server Error: /inscribir_curso/
Traceback (most recent call last):
  File "C:\Users\Gonzalo\Desktop\punto_fitness\env\Lib\site-packages\django\db\backends\utils.py", line 105, in _execute
    return self.cursor.execute(sql, params)
           ~~~~~~~~~~~~~~~~~~~^^^^^^^^^^^^^
psycopg2.errors.UniqueViolation: llave duplicada viola restricción de unicidad «inscripcion_usuario_id_curso_id_fecha_realizacion_fb7ade3f_uniq»
DETAIL:  Ya existe la llave (usuario_id, curso_id, fecha_realizacion)=(4, 3, 2025-06-11).


The above exception was the direct cause of the following exception:

Traceback (most recent call last):
  File "C:\Users\Gonzalo\Desktop\punto_fitness\env\Lib\site-packages\django\core\handlers\exception.py", line 55, in inner
    response = get_response(request)
  File "C:\Users\Gonzalo\Desktop\punto_fitness\env\Lib\site-packages\django\core\handlers\base.py", line 197, in _get_response
    response = wrapped_callback(request, *callback_args, **callback_kwargs)
  File "C:\Users\Gonzalo\Desktop\punto_fitness\punto_fitness\punto_app\views.py", line 433, in inscribir_curso
    inscripcion = Inscripcion.objects.create(
        usuario_id=data['usuario_id'],
        curso_id=data['curso_id'],
        fecha_inscripcion=timezone.now()
    )
  File "C:\Users\Gonzalo\Desktop\punto_fitness\env\Lib\site-packages\django\db\models\manager.py", line 87, in manager_method
    return getattr(self.get_queryset(), name)(*args, **kwargs)
           ~~~~~~~~~~~~~~~~~~~~~~~~~~~~~~~~~~^^^^^^^^^^^^^^^^^
  File "C:\Users\Gonzalo\Desktop\punto_fitness\env\Lib\site-packages\django\db\models\query.py", line 663, in create
    obj.save(force_insert=True, using=self.db)
    ~~~~~~~~^^^^^^^^^^^^^^^^^^^^^^^^^^^^^^^^^^
  File "C:\Users\Gonzalo\Desktop\punto_fitness\punto_fitness\punto_app\models.py", line 215, in save
    super().save(*args, **kwargs)
    ~~~~~~~~~~~~^^^^^^^^^^^^^^^^^
  File "C:\Users\Gonzalo\Desktop\punto_fitness\env\Lib\site-packages\django\db\models\base.py", line 902, in save
    self.save_base(
    ~~~~~~~~~~~~~~^
        using=using,
        ^^^^^^^^^^^^
    ...<2 lines>...
        update_fields=update_fields,
        ^^^^^^^^^^^^^^^^^^^^^^^^^^^^
    )
    ^
  File "C:\Users\Gonzalo\Desktop\punto_fitness\env\Lib\site-packages\django\db\models\base.py", line 1008, in save_base
    updated = self._save_table(
        raw,
    ...<4 lines>...
        update_fields,
    )
  File "C:\Users\Gonzalo\Desktop\punto_fitness\env\Lib\site-packages\django\db\models\base.py", line 1169, in _save_table
    results = self._do_insert(
        cls._base_manager, using, fields, returning_fields, raw
    )
  File "C:\Users\Gonzalo\Desktop\punto_fitness\env\Lib\site-packages\django\db\models\base.py", line 1210, in _do_insert
    return manager._insert(
           ~~~~~~~~~~~~~~~^
        [self],
        ^^^^^^^
    ...<3 lines>...
        raw=raw,
        ^^^^^^^^
    )
    ^
  File "C:\Users\Gonzalo\Desktop\punto_fitness\env\Lib\site-packages\django\db\models\manager.py", line 87, in manager_method
    return getattr(self.get_queryset(), name)(*args, **kwargs)
           ~~~~~~~~~~~~~~~~~~~~~~~~~~~~~~~~~~^^^^^^^^^^^^^^^^^
  File "C:\Users\Gonzalo\Desktop\punto_fitness\env\Lib\site-packages\django\db\models\query.py", line 1868, in _insert
    return query.get_compiler(using=using).execute_sql(returning_fields)
           ~~~~~~~~~~~~~~~~~~~~~~~~~~~~~~~~~~~~~~~~~~~^^^^^^^^^^^^^^^^^^
  File "C:\Users\Gonzalo\Desktop\punto_fitness\env\Lib\site-packages\django\db\models\sql\compiler.py", line 1882, in execute_sql
    cursor.execute(sql, params)
    ~~~~~~~~~~~~~~^^^^^^^^^^^^^
  File "C:\Users\Gonzalo\Desktop\punto_fitness\env\Lib\site-packages\django\db\backends\utils.py", line 122, in execute
    return super().execute(sql, params)
           ~~~~~~~~~~~~~~~^^^^^^^^^^^^^
  File "C:\Users\Gonzalo\Desktop\punto_fitness\env\Lib\site-packages\django\db\backends\utils.py", line 79, in execute
    return self._execute_with_wrappers(
           ~~~~~~~~~~~~~~~~~~~~~~~~~~~^
        sql, params, many=False, executor=self._execute
        ^^^^^^^^^^^^^^^^^^^^^^^^^^^^^^^^^^^^^^^^^^^^^^^
    )
    ^
  File "C:\Users\Gonzalo\Desktop\punto_fitness\env\Lib\site-packages\django\db\backends\utils.py", line 92, in _execute_with_wrappers
    return executor(sql, params, many, context)
  File "C:\Users\Gonzalo\Desktop\punto_fitness\env\Lib\site-packages\django\db\backends\utils.py", line 100, in _execute
    with self.db.wrap_database_errors:
         ^^^^^^^^^^^^^^^^^^^^^^^^^^^^
  File "C:\Users\Gonzalo\Desktop\punto_fitness\env\Lib\site-packages\django\db\utils.py", line 91, in __exit__
    raise dj_exc_value.with_traceback(traceback) from exc_value
  File "C:\Users\Gonzalo\Desktop\punto_fitness\env\Lib\site-packages\django\db\backends\utils.py", line 105, in _execute
    return self.cursor.execute(sql, params)
           ~~~~~~~~~~~~~~~~~~~^^^^^^^^^^^^^
django.db.utils.IntegrityError: llave duplicada viola restricción de unicidad «inscripcion_usuario_id_curso_id_fecha_realizacion_fb7ade3f_uniq»
DETAIL:  Ya existe la llave (usuario_id, curso_id, fecha_realizacion)=(4, 3, 2025-06-11).

ERROR 2025-06-09 01:29:49,356 basehttp 1188 3048 "POST /inscribir_curso/ HTTP/1.1" 500 157630
ERROR 2025-06-09 01:31:27,888 log 6436 11456 Internal Server Error: /inscribir_curso/
Traceback (most recent call last):
  File "C:\Users\Gonzalo\Desktop\punto_fitness\env\Lib\site-packages\django\db\backends\utils.py", line 105, in _execute
    return self.cursor.execute(sql, params)
           ~~~~~~~~~~~~~~~~~~~^^^^^^^^^^^^^
psycopg2.errors.UniqueViolation: llave duplicada viola restricción de unicidad «inscripcion_usuario_id_curso_id_fecha_realizacion_fb7ade3f_uniq»
DETAIL:  Ya existe la llave (usuario_id, curso_id, fecha_realizacion)=(4, 3, 2025-06-11).


The above exception was the direct cause of the following exception:

Traceback (most recent call last):
  File "C:\Users\Gonzalo\Desktop\punto_fitness\env\Lib\site-packages\django\core\handlers\exception.py", line 55, in inner
    response = get_response(request)
  File "C:\Users\Gonzalo\Desktop\punto_fitness\env\Lib\site-packages\django\core\handlers\base.py", line 197, in _get_response
    response = wrapped_callback(request, *callback_args, **callback_kwargs)
  File "C:\Users\Gonzalo\Desktop\punto_fitness\punto_fitness\punto_app\views.py", line 433, in inscribir_curso
    inscripcion = Inscripcion.objects.create(
        usuario_id=data['usuario_id'],
        curso_id=data['curso_id'],
        fecha_inscripcion=timezone.now()
    )
  File "C:\Users\Gonzalo\Desktop\punto_fitness\env\Lib\site-packages\django\db\models\manager.py", line 87, in manager_method
    return getattr(self.get_queryset(), name)(*args, **kwargs)
           ~~~~~~~~~~~~~~~~~~~~~~~~~~~~~~~~~~^^^^^^^^^^^^^^^^^
  File "C:\Users\Gonzalo\Desktop\punto_fitness\env\Lib\site-packages\django\db\models\query.py", line 663, in create
    obj.save(force_insert=True, using=self.db)
    ~~~~~~~~^^^^^^^^^^^^^^^^^^^^^^^^^^^^^^^^^^
  File "C:\Users\Gonzalo\Desktop\punto_fitness\punto_fitness\punto_app\models.py", line 215, in save
    super().save(*args, **kwargs)
    ~~~~~~~~~~~~^^^^^^^^^^^^^^^^^
  File "C:\Users\Gonzalo\Desktop\punto_fitness\env\Lib\site-packages\django\db\models\base.py", line 902, in save
    self.save_base(
    ~~~~~~~~~~~~~~^
        using=using,
        ^^^^^^^^^^^^
    ...<2 lines>...
        update_fields=update_fields,
        ^^^^^^^^^^^^^^^^^^^^^^^^^^^^
    )
    ^
  File "C:\Users\Gonzalo\Desktop\punto_fitness\env\Lib\site-packages\django\db\models\base.py", line 1008, in save_base
    updated = self._save_table(
        raw,
    ...<4 lines>...
        update_fields,
    )
  File "C:\Users\Gonzalo\Desktop\punto_fitness\env\Lib\site-packages\django\db\models\base.py", line 1169, in _save_table
    results = self._do_insert(
        cls._base_manager, using, fields, returning_fields, raw
    )
  File "C:\Users\Gonzalo\Desktop\punto_fitness\env\Lib\site-packages\django\db\models\base.py", line 1210, in _do_insert
    return manager._insert(
           ~~~~~~~~~~~~~~~^
        [self],
        ^^^^^^^
    ...<3 lines>...
        raw=raw,
        ^^^^^^^^
    )
    ^
  File "C:\Users\Gonzalo\Desktop\punto_fitness\env\Lib\site-packages\django\db\models\manager.py", line 87, in manager_method
    return getattr(self.get_queryset(), name)(*args, **kwargs)
           ~~~~~~~~~~~~~~~~~~~~~~~~~~~~~~~~~~^^^^^^^^^^^^^^^^^
  File "C:\Users\Gonzalo\Desktop\punto_fitness\env\Lib\site-packages\django\db\models\query.py", line 1868, in _insert
    return query.get_compiler(using=using).execute_sql(returning_fields)
           ~~~~~~~~~~~~~~~~~~~~~~~~~~~~~~~~~~~~~~~~~~~^^^^^^^^^^^^^^^^^^
  File "C:\Users\Gonzalo\Desktop\punto_fitness\env\Lib\site-packages\django\db\models\sql\compiler.py", line 1882, in execute_sql
    cursor.execute(sql, params)
    ~~~~~~~~~~~~~~^^^^^^^^^^^^^
  File "C:\Users\Gonzalo\Desktop\punto_fitness\env\Lib\site-packages\django\db\backends\utils.py", line 122, in execute
    return super().execute(sql, params)
           ~~~~~~~~~~~~~~~^^^^^^^^^^^^^
  File "C:\Users\Gonzalo\Desktop\punto_fitness\env\Lib\site-packages\django\db\backends\utils.py", line 79, in execute
    return self._execute_with_wrappers(
           ~~~~~~~~~~~~~~~~~~~~~~~~~~~^
        sql, params, many=False, executor=self._execute
        ^^^^^^^^^^^^^^^^^^^^^^^^^^^^^^^^^^^^^^^^^^^^^^^
    )
    ^
  File "C:\Users\Gonzalo\Desktop\punto_fitness\env\Lib\site-packages\django\db\backends\utils.py", line 92, in _execute_with_wrappers
    return executor(sql, params, many, context)
  File "C:\Users\Gonzalo\Desktop\punto_fitness\env\Lib\site-packages\django\db\backends\utils.py", line 100, in _execute
    with self.db.wrap_database_errors:
         ^^^^^^^^^^^^^^^^^^^^^^^^^^^^
  File "C:\Users\Gonzalo\Desktop\punto_fitness\env\Lib\site-packages\django\db\utils.py", line 91, in __exit__
    raise dj_exc_value.with_traceback(traceback) from exc_value
  File "C:\Users\Gonzalo\Desktop\punto_fitness\env\Lib\site-packages\django\db\backends\utils.py", line 105, in _execute
    return self.cursor.execute(sql, params)
           ~~~~~~~~~~~~~~~~~~~^^^^^^^^^^^^^
django.db.utils.IntegrityError: llave duplicada viola restricción de unicidad «inscripcion_usuario_id_curso_id_fecha_realizacion_fb7ade3f_uniq»
DETAIL:  Ya existe la llave (usuario_id, curso_id, fecha_realizacion)=(4, 3, 2025-06-11).

ERROR 2025-06-09 01:31:27,899 basehttp 6436 11456 "POST /inscribir_curso/ HTTP/1.1" 500 157630
ERROR 2025-06-09 01:33:35,544 log 2152 6824 Internal Server Error: /inscribir_curso/
Traceback (most recent call last):
  File "C:\Users\Gonzalo\Desktop\punto_fitness\env\Lib\site-packages\django\db\backends\utils.py", line 105, in _execute
    return self.cursor.execute(sql, params)
           ~~~~~~~~~~~~~~~~~~~^^^^^^^^^^^^^
psycopg2.errors.UniqueViolation: llave duplicada viola restricción de unicidad «inscripcion_usuario_id_curso_id_fecha_realizacion_fb7ade3f_uniq»
DETAIL:  Ya existe la llave (usuario_id, curso_id, fecha_realizacion)=(4, 3, 2025-06-11).


The above exception was the direct cause of the following exception:

Traceback (most recent call last):
  File "C:\Users\Gonzalo\Desktop\punto_fitness\env\Lib\site-packages\django\core\handlers\exception.py", line 55, in inner
    response = get_response(request)
  File "C:\Users\Gonzalo\Desktop\punto_fitness\env\Lib\site-packages\django\core\handlers\base.py", line 197, in _get_response
    response = wrapped_callback(request, *callback_args, **callback_kwargs)
  File "C:\Users\Gonzalo\Desktop\punto_fitness\punto_fitness\punto_app\views.py", line 433, in inscribir_curso
    inscripcion = Inscripcion.objects.create(
        usuario_id=data['usuario_id'],
        curso_id=data['curso_id'],
        fecha_inscripcion=timezone.now()
    )
  File "C:\Users\Gonzalo\Desktop\punto_fitness\env\Lib\site-packages\django\db\models\manager.py", line 87, in manager_method
    return getattr(self.get_queryset(), name)(*args, **kwargs)
           ~~~~~~~~~~~~~~~~~~~~~~~~~~~~~~~~~~^^^^^^^^^^^^^^^^^
  File "C:\Users\Gonzalo\Desktop\punto_fitness\env\Lib\site-packages\django\db\models\query.py", line 663, in create
    obj.save(force_insert=True, using=self.db)
    ~~~~~~~~^^^^^^^^^^^^^^^^^^^^^^^^^^^^^^^^^^
  File "C:\Users\Gonzalo\Desktop\punto_fitness\punto_fitness\punto_app\models.py", line 215, in save
    super().save(*args, **kwargs)
    ~~~~~~~~~~~~^^^^^^^^^^^^^^^^^
  File "C:\Users\Gonzalo\Desktop\punto_fitness\env\Lib\site-packages\django\db\models\base.py", line 902, in save
    self.save_base(
    ~~~~~~~~~~~~~~^
        using=using,
        ^^^^^^^^^^^^
    ...<2 lines>...
        update_fields=update_fields,
        ^^^^^^^^^^^^^^^^^^^^^^^^^^^^
    )
    ^
  File "C:\Users\Gonzalo\Desktop\punto_fitness\env\Lib\site-packages\django\db\models\base.py", line 1008, in save_base
    updated = self._save_table(
        raw,
    ...<4 lines>...
        update_fields,
    )
  File "C:\Users\Gonzalo\Desktop\punto_fitness\env\Lib\site-packages\django\db\models\base.py", line 1169, in _save_table
    results = self._do_insert(
        cls._base_manager, using, fields, returning_fields, raw
    )
  File "C:\Users\Gonzalo\Desktop\punto_fitness\env\Lib\site-packages\django\db\models\base.py", line 1210, in _do_insert
    return manager._insert(
           ~~~~~~~~~~~~~~~^
        [self],
        ^^^^^^^
    ...<3 lines>...
        raw=raw,
        ^^^^^^^^
    )
    ^
  File "C:\Users\Gonzalo\Desktop\punto_fitness\env\Lib\site-packages\django\db\models\manager.py", line 87, in manager_method
    return getattr(self.get_queryset(), name)(*args, **kwargs)
           ~~~~~~~~~~~~~~~~~~~~~~~~~~~~~~~~~~^^^^^^^^^^^^^^^^^
  File "C:\Users\Gonzalo\Desktop\punto_fitness\env\Lib\site-packages\django\db\models\query.py", line 1868, in _insert
    return query.get_compiler(using=using).execute_sql(returning_fields)
           ~~~~~~~~~~~~~~~~~~~~~~~~~~~~~~~~~~~~~~~~~~~^^^^^^^^^^^^^^^^^^
  File "C:\Users\Gonzalo\Desktop\punto_fitness\env\Lib\site-packages\django\db\models\sql\compiler.py", line 1882, in execute_sql
    cursor.execute(sql, params)
    ~~~~~~~~~~~~~~^^^^^^^^^^^^^
  File "C:\Users\Gonzalo\Desktop\punto_fitness\env\Lib\site-packages\django\db\backends\utils.py", line 122, in execute
    return super().execute(sql, params)
           ~~~~~~~~~~~~~~~^^^^^^^^^^^^^
  File "C:\Users\Gonzalo\Desktop\punto_fitness\env\Lib\site-packages\django\db\backends\utils.py", line 79, in execute
    return self._execute_with_wrappers(
           ~~~~~~~~~~~~~~~~~~~~~~~~~~~^
        sql, params, many=False, executor=self._execute
        ^^^^^^^^^^^^^^^^^^^^^^^^^^^^^^^^^^^^^^^^^^^^^^^
    )
    ^
  File "C:\Users\Gonzalo\Desktop\punto_fitness\env\Lib\site-packages\django\db\backends\utils.py", line 92, in _execute_with_wrappers
    return executor(sql, params, many, context)
  File "C:\Users\Gonzalo\Desktop\punto_fitness\env\Lib\site-packages\django\db\backends\utils.py", line 100, in _execute
    with self.db.wrap_database_errors:
         ^^^^^^^^^^^^^^^^^^^^^^^^^^^^
  File "C:\Users\Gonzalo\Desktop\punto_fitness\env\Lib\site-packages\django\db\utils.py", line 91, in __exit__
    raise dj_exc_value.with_traceback(traceback) from exc_value
  File "C:\Users\Gonzalo\Desktop\punto_fitness\env\Lib\site-packages\django\db\backends\utils.py", line 105, in _execute
    return self.cursor.execute(sql, params)
           ~~~~~~~~~~~~~~~~~~~^^^^^^^^^^^^^
django.db.utils.IntegrityError: llave duplicada viola restricción de unicidad «inscripcion_usuario_id_curso_id_fecha_realizacion_fb7ade3f_uniq»
DETAIL:  Ya existe la llave (usuario_id, curso_id, fecha_realizacion)=(4, 3, 2025-06-11).

ERROR 2025-06-09 01:33:35,556 basehttp 2152 6824 "POST /inscribir_curso/ HTTP/1.1" 500 157630
ERROR 2025-06-09 13:49:16,161 log 13980 7508 Internal Server Error: /
Traceback (most recent call last):
  File "C:\Users\Gonzalo\Desktop\punto_fitness\env\Lib\site-packages\django\template\base.py", line 510, in parse
    compile_func = self.tags[command]
                   ~~~~~~~~~^^^^^^^^^
KeyError: "'principal'"

During handling of the above exception, another exception occurred:

Traceback (most recent call last):
  File "C:\Users\Gonzalo\Desktop\punto_fitness\env\Lib\site-packages\django\core\handlers\exception.py", line 55, in inner
    response = get_response(request)
  File "C:\Users\Gonzalo\Desktop\punto_fitness\env\Lib\site-packages\django\core\handlers\base.py", line 197, in _get_response
    response = wrapped_callback(request, *callback_args, **callback_kwargs)
  File "C:\Users\Gonzalo\Desktop\punto_fitness\punto_fitness\punto_app\views.py", line 23, in principal
    return render(request, 'punto_app/principal.html')
  File "C:\Users\Gonzalo\Desktop\punto_fitness\env\Lib\site-packages\django\shortcuts.py", line 25, in render
    content = loader.render_to_string(template_name, context, request, using=using)
  File "C:\Users\Gonzalo\Desktop\punto_fitness\env\Lib\site-packages\django\template\loader.py", line 62, in render_to_string
    return template.render(context, request)
           ~~~~~~~~~~~~~~~^^^^^^^^^^^^^^^^^^
  File "C:\Users\Gonzalo\Desktop\punto_fitness\env\Lib\site-packages\django\template\backends\django.py", line 107, in render
    return self.template.render(context)
           ~~~~~~~~~~~~~~~~~~~~^^^^^^^^^
  File "C:\Users\Gonzalo\Desktop\punto_fitness\env\Lib\site-packages\django\template\base.py", line 171, in render
    return self._render(context)
           ~~~~~~~~~~~~^^^^^^^^^
  File "C:\Users\Gonzalo\Desktop\punto_fitness\env\Lib\site-packages\django\template\base.py", line 163, in _render
    return self.nodelist.render(context)
           ~~~~~~~~~~~~~~~~~~~~^^^^^^^^^
  File "C:\Users\Gonzalo\Desktop\punto_fitness\env\Lib\site-packages\django\template\base.py", line 1016, in render
    return SafeString("".join([node.render_annotated(context) for node in self]))
                               ~~~~~~~~~~~~~~~~~~~~~^^^^^^^^^
  File "C:\Users\Gonzalo\Desktop\punto_fitness\env\Lib\site-packages\django\template\base.py", line 977, in render_annotated
    return self.render(context)
           ~~~~~~~~~~~^^^^^^^^^
  File "C:\Users\Gonzalo\Desktop\punto_fitness\env\Lib\site-packages\django\template\loader_tags.py", line 134, in render
    compiled_parent = self.get_parent(context)
  File "C:\Users\Gonzalo\Desktop\punto_fitness\env\Lib\site-packages\django\template\loader_tags.py", line 131, in get_parent
    return self.find_template(parent, context)
           ~~~~~~~~~~~~~~~~~~^^^^^^^^^^^^^^^^^
  File "C:\Users\Gonzalo\Desktop\punto_fitness\env\Lib\site-packages\django\template\loader_tags.py", line 109, in find_template
    template, origin = context.template.engine.find_template(
                       ~~~~~~~~~~~~~~~~~~~~~~~~~~~~~~~~~~~~~^
        template_name,
        ^^^^^^^^^^^^^^
        skip=history,
        ^^^^^^^^^^^^^
    )
    ^
  File "C:\Users\Gonzalo\Desktop\punto_fitness\env\Lib\site-packages\django\template\engine.py", line 159, in find_template
    template = loader.get_template(name, skip=skip)
  File "C:\Users\Gonzalo\Desktop\punto_fitness\env\Lib\site-packages\django\template\loaders\cached.py", line 57, in get_template
    template = super().get_template(template_name, skip)
  File "C:\Users\Gonzalo\Desktop\punto_fitness\env\Lib\site-packages\django\template\loaders\base.py", line 28, in get_template
    return Template(
        contents,
    ...<2 lines>...
        self.engine,
    )
  File "C:\Users\Gonzalo\Desktop\punto_fitness\env\Lib\site-packages\django\template\base.py", line 154, in __init__
    self.nodelist = self.compile_nodelist()
                    ~~~~~~~~~~~~~~~~~~~~~^^
  File "C:\Users\Gonzalo\Desktop\punto_fitness\env\Lib\site-packages\django\template\base.py", line 196, in compile_nodelist
    nodelist = parser.parse()
  File "C:\Users\Gonzalo\Desktop\punto_fitness\env\Lib\site-packages\django\template\base.py", line 512, in parse
    self.invalid_block_tag(token, command, parse_until)
    ~~~~~~~~~~~~~~~~~~~~~~^^^^^^^^^^^^^^^^^^^^^^^^^^^^^
  File "C:\Users\Gonzalo\Desktop\punto_fitness\env\Lib\site-packages\django\template\base.py", line 577, in invalid_block_tag
    raise self.error(
    ...<3 lines>...
    )
django.template.exceptions.TemplateSyntaxError: Invalid block tag on line 26: ''principal''. Did you forget to register or load this tag?
ERROR 2025-06-09 13:49:16,179 basehttp 13980 7508 "GET / HTTP/1.1" 500 188014
ERROR 2025-06-11 21:12:21,995 views 6912 14708 Error al obtener imágenes: expected str, bytes or os.PathLike object, not list
ERROR 2025-06-11 21:12:21,998 log 6912 14708 Internal Server Error: /obtener_imagenes_productos/
ERROR 2025-06-11 21:12:22,030 basehttp 6912 14708 "GET /obtener_imagenes_productos/ HTTP/1.1" 500 64
ERROR 2025-06-11 21:12:23,422 views 6912 20796 Error al obtener imágenes: expected str, bytes or os.PathLike object, not list
ERROR 2025-06-11 21:12:23,422 log 6912 20796 Internal Server Error: /obtener_imagenes_productos/
ERROR 2025-06-11 21:12:23,425 basehttp 6912 20796 "GET /obtener_imagenes_productos/ HTTP/1.1" 500 64
ERROR 2025-06-11 21:14:27,750 views 9304 20268 Error al obtener imágenes: expected str, bytes or os.PathLike object, not list
ERROR 2025-06-11 21:14:27,752 log 9304 20268 Internal Server Error: /obtener_imagenes_productos/
ERROR 2025-06-11 21:14:27,752 basehttp 9304 20268 "GET /obtener_imagenes_productos/ HTTP/1.1" 500 64
ERROR 2025-06-11 21:14:29,361 views 9304 20268 Error al obtener imágenes: expected str, bytes or os.PathLike object, not list
ERROR 2025-06-11 21:14:29,362 log 9304 20268 Internal Server Error: /obtener_imagenes_productos/
ERROR 2025-06-11 21:14:29,362 basehttp 9304 20268 "GET /obtener_imagenes_productos/ HTTP/1.1" 500 64
