ERROR 2025-06-07 00:51:37,524 exception 16020 6052 Invalid HTTP_HOST header: '127.0.0.1:8000'. You may need to add '127.0.0.1' to ALLOWED_HOSTS.
Traceback (most recent call last):
  File "C:\Users\Gonzalo\Desktop\punto_fitness\env\Lib\site-packages\django\core\handlers\exception.py", line 55, in inner
    response = get_response(request)
  File "C:\Users\Gonzalo\Desktop\punto_fitness\env\Lib\site-packages\django\utils\deprecation.py", line 119, in __call__
    response = self.process_request(request)
  File "C:\Users\Gonzalo\Desktop\punto_fitness\env\Lib\site-packages\django\middleware\common.py", line 48, in process_request
    host = request.get_host()
  File "C:\Users\Gonzalo\Desktop\punto_fitness\env\Lib\site-packages\django\http\request.py", line 191, in get_host
    raise DisallowedHost(msg)
django.core.exceptions.DisallowedHost: Invalid HTTP_HOST header: '127.0.0.1:8000'. You may need to add '127.0.0.1' to ALLOWED_HOSTS.
ERROR 2025-06-07 00:51:37,790 exception 16020 18568 Invalid HTTP_HOST header: '127.0.0.1:8000'. You may need to add '127.0.0.1' to ALLOWED_HOSTS.
Traceback (most recent call last):
  File "C:\Users\Gonzalo\Desktop\punto_fitness\env\Lib\site-packages\django\core\handlers\exception.py", line 55, in inner
    response = get_response(request)
  File "C:\Users\Gonzalo\Desktop\punto_fitness\env\Lib\site-packages\django\utils\deprecation.py", line 119, in __call__
    response = self.process_request(request)
  File "C:\Users\Gonzalo\Desktop\punto_fitness\env\Lib\site-packages\django\middleware\common.py", line 48, in process_request
    host = request.get_host()
  File "C:\Users\Gonzalo\Desktop\punto_fitness\env\Lib\site-packages\django\http\request.py", line 191, in get_host
    raise DisallowedHost(msg)
django.core.exceptions.DisallowedHost: Invalid HTTP_HOST header: '127.0.0.1:8000'. You may need to add '127.0.0.1' to ALLOWED_HOSTS.
ERROR 2025-06-07 01:48:12,831 log 14428 16528 Internal Server Error: /cambiar-rol-admin/
Traceback (most recent call last):
  File "C:\Users\Gonzalo\Desktop\punto_fitness\env\Lib\site-packages\django\core\handlers\exception.py", line 55, in inner
    response = get_response(request)
  File "C:\Users\Gonzalo\Desktop\punto_fitness\env\Lib\site-packages\django\core\handlers\base.py", line 197, in _get_response
    response = wrapped_callback(request, *callback_args, **callback_kwargs)
  File "C:\Users\Gonzalo\Desktop\punto_fitness\env\Lib\site-packages\django\views\decorators\csrf.py", line 65, in _view_wrapper
    return view_func(request, *args, **kwargs)
  File "C:\Users\Gonzalo\Desktop\punto_fitness\punto_fitness\punto_app\views.py", line 927, in cambiar_rol_admin
    admin, created = Administrador.objects.get_or_create(
                     ~~~~~~~~~~~~~~~~~~~~~~~~~~~~~~~~~~~^
        id_cliente=cliente,
        ^^^^^^^^^^^^^^^^^^^
        defaults={'nivel_acceso': 'admin', 'establecimiento_id': establecimiento_id}
        ^^^^^^^^^^^^^^^^^^^^^^^^^^^^^^^^^^^^^^^^^^^^^^^^^^^^^^^^^^^^^^^^^^^^^^^^^^^^
    )
    ^
  File "C:\Users\Gonzalo\Desktop\punto_fitness\env\Lib\site-packages\django\db\models\manager.py", line 87, in manager_method
    return getattr(self.get_queryset(), name)(*args, **kwargs)
           ~~~~~~~~~~~~~~~~~~~~~~~~~~~~~~~~~~^^^^^^^^^^^^^^^^^
  File "C:\Users\Gonzalo\Desktop\punto_fitness\env\Lib\site-packages\django\db\models\query.py", line 946, in get_or_create
    return self.get(**kwargs), False
           ~~~~~~~~^^^^^^^^^^
  File "C:\Users\Gonzalo\Desktop\punto_fitness\env\Lib\site-packages\django\db\models\query.py", line 619, in get
    clone = self._chain() if self.query.combinator else self.filter(*args, **kwargs)
                                                        ~~~~~~~~~~~^^^^^^^^^^^^^^^^^
  File "C:\Users\Gonzalo\Desktop\punto_fitness\env\Lib\site-packages\django\db\models\query.py", line 1493, in filter
    return self._filter_or_exclude(False, args, kwargs)
           ~~~~~~~~~~~~~~~~~~~~~~~^^^^^^^^^^^^^^^^^^^^^
  File "C:\Users\Gonzalo\Desktop\punto_fitness\env\Lib\site-packages\django\db\models\query.py", line 1511, in _filter_or_exclude
    clone._filter_or_exclude_inplace(negate, args, kwargs)
    ~~~~~~~~~~~~~~~~~~~~~~~~~~~~~~~~^^^^^^^^^^^^^^^^^^^^^^
  File "C:\Users\Gonzalo\Desktop\punto_fitness\env\Lib\site-packages\django\db\models\query.py", line 1518, in _filter_or_exclude_inplace
    self._query.add_q(Q(*args, **kwargs))
    ~~~~~~~~~~~~~~~~~^^^^^^^^^^^^^^^^^^^^
  File "C:\Users\Gonzalo\Desktop\punto_fitness\env\Lib\site-packages\django\db\models\sql\query.py", line 1646, in add_q
    clause, _ = self._add_q(q_object, can_reuse)
                ~~~~~~~~~~~^^^^^^^^^^^^^^^^^^^^^
  File "C:\Users\Gonzalo\Desktop\punto_fitness\env\Lib\site-packages\django\db\models\sql\query.py", line 1678, in _add_q
    child_clause, needed_inner = self.build_filter(
                                 ~~~~~~~~~~~~~~~~~^
        child,
        ^^^^^^
    ...<7 lines>...
        update_join_types=update_join_types,
        ^^^^^^^^^^^^^^^^^^^^^^^^^^^^^^^^^^^^
    )
    ^
  File "C:\Users\Gonzalo\Desktop\punto_fitness\env\Lib\site-packages\django\db\models\sql\query.py", line 1526, in build_filter
    lookups, parts, reffed_expression = self.solve_lookup_type(arg, summarize)
                                        ~~~~~~~~~~~~~~~~~~~~~~^^^^^^^^^^^^^^^^
  File "C:\Users\Gonzalo\Desktop\punto_fitness\env\Lib\site-packages\django\db\models\sql\query.py", line 1333, in solve_lookup_type
    _, field, _, lookup_parts = self.names_to_path(lookup_splitted, self.get_meta())
                                ~~~~~~~~~~~~~~~~~~^^^^^^^^^^^^^^^^^^^^^^^^^^^^^^^^^^
  File "C:\Users\Gonzalo\Desktop\punto_fitness\env\Lib\site-packages\django\db\models\sql\query.py", line 1805, in names_to_path
    raise FieldError(
    ...<2 lines>...
    )
django.core.exceptions.FieldError: Cannot resolve keyword 'id_cliente' into field. Choices are: cliente, cliente_id, establecimiento, establecimiento_id, id, nivel_acceso
ERROR 2025-06-07 01:48:12,842 basehttp 14428 16528 "POST /cambiar-rol-admin/ HTTP/1.1" 500 129361
ERROR 2025-06-07 02:29:50,808 log 16576 7836 Internal Server Error: /admin-dashboard/
Traceback (most recent call last):
  File "C:\Users\Gonzalo\Desktop\punto_fitness\env\Lib\site-packages\django\core\handlers\exception.py", line 55, in inner
    response = get_response(request)
  File "C:\Users\Gonzalo\Desktop\punto_fitness\env\Lib\site-packages\django\core\handlers\base.py", line 197, in _get_response
    response = wrapped_callback(request, *callback_args, **callback_kwargs)
  File "C:\Users\Gonzalo\Desktop\punto_fitness\punto_fitness\punto_app\views.py", line 183, in pagina_admin
    return render(request, 'punto_app/pagina_admin.html')
  File "C:\Users\Gonzalo\Desktop\punto_fitness\env\Lib\site-packages\django\shortcuts.py", line 25, in render
    content = loader.render_to_string(template_name, context, request, using=using)
  File "C:\Users\Gonzalo\Desktop\punto_fitness\env\Lib\site-packages\django\template\loader.py", line 61, in render_to_string
    template = get_template(template_name, using=using)
  File "C:\Users\Gonzalo\Desktop\punto_fitness\env\Lib\site-packages\django\template\loader.py", line 19, in get_template
    raise TemplateDoesNotExist(template_name, chain=chain)
django.template.exceptions.TemplateDoesNotExist: punto_app/pagina_admin.html
ERROR 2025-06-07 02:29:50,812 basehttp 16576 7836 "GET /admin-dashboard/ HTTP/1.1" 500 85663
ERROR 2025-06-07 02:51:50,931 log 9572 7700 Internal Server Error: /admin-dashboard/
Traceback (most recent call last):
  File "C:\Users\Gonzalo\Desktop\punto_fitness\env\Lib\site-packages\django\core\handlers\exception.py", line 55, in inner
    response = get_response(request)
  File "C:\Users\Gonzalo\Desktop\punto_fitness\env\Lib\site-packages\django\core\handlers\base.py", line 197, in _get_response
    response = wrapped_callback(request, *callback_args, **callback_kwargs)
  File "C:\Users\Gonzalo\Desktop\punto_fitness\punto_fitness\punto_app\views.py", line 168, in pagina_admin
    return render(request, 'punto_app/admin_dashboard.html')
  File "C:\Users\Gonzalo\Desktop\punto_fitness\env\Lib\site-packages\django\shortcuts.py", line 25, in render
    content = loader.render_to_string(template_name, context, request, using=using)
  File "C:\Users\Gonzalo\Desktop\punto_fitness\env\Lib\site-packages\django\template\loader.py", line 62, in render_to_string
    return template.render(context, request)
           ~~~~~~~~~~~~~~~^^^^^^^^^^^^^^^^^^
  File "C:\Users\Gonzalo\Desktop\punto_fitness\env\Lib\site-packages\django\template\backends\django.py", line 107, in render
    return self.template.render(context)
           ~~~~~~~~~~~~~~~~~~~~^^^^^^^^^
  File "C:\Users\Gonzalo\Desktop\punto_fitness\env\Lib\site-packages\django\template\base.py", line 169, in render
    with context.bind_template(self):
         ~~~~~~~~~~~~~~~~~~~~~^^^^^^
  File "C:\Python313\Lib\contextlib.py", line 141, in __enter__
    return next(self.gen)
  File "C:\Users\Gonzalo\Desktop\punto_fitness\env\Lib\site-packages\django\template\context.py", line 259, in bind_template
    context = processor(self.request)
  File "C:\Users\Gonzalo\Desktop\punto_fitness\punto_fitness\punto_app\context_processors.py", line 12, in user_info
    cliente_data['cliente_email'] = cliente.correo
                                    ^^^^^^^^^^^^^^
AttributeError: 'Cliente' object has no attribute 'correo'
ERROR 2025-06-07 02:51:50,937 basehttp 9572 7700 "GET /admin-dashboard/ HTTP/1.1" 500 101986
ERROR 2025-06-09 01:29:49,342 log 1188 3048 Internal Server Error: /inscribir_curso/
Traceback (most recent call last):
  File "C:\Users\Gonzalo\Desktop\punto_fitness\env\Lib\site-packages\django\db\backends\utils.py", line 105, in _execute
    return self.cursor.execute(sql, params)
           ~~~~~~~~~~~~~~~~~~~^^^^^^^^^^^^^
psycopg2.errors.UniqueViolation: llave duplicada viola restricción de unicidad «inscripcion_usuario_id_curso_id_fecha_realizacion_fb7ade3f_uniq»
DETAIL:  Ya existe la llave (usuario_id, curso_id, fecha_realizacion)=(4, 3, 2025-06-11).


The above exception was the direct cause of the following exception:

Traceback (most recent call last):
  File "C:\Users\Gonzalo\Desktop\punto_fitness\env\Lib\site-packages\django\core\handlers\exception.py", line 55, in inner
    response = get_response(request)
  File "C:\Users\Gonzalo\Desktop\punto_fitness\env\Lib\site-packages\django\core\handlers\base.py", line 197, in _get_response
    response = wrapped_callback(request, *callback_args, **callback_kwargs)
  File "C:\Users\Gonzalo\Desktop\punto_fitness\punto_fitness\punto_app\views.py", line 433, in inscribir_curso
    inscripcion = Inscripcion.objects.create(
        usuario_id=data['usuario_id'],
        curso_id=data['curso_id'],
        fecha_inscripcion=timezone.now()
    )
  File "C:\Users\Gonzalo\Desktop\punto_fitness\env\Lib\site-packages\django\db\models\manager.py", line 87, in manager_method
    return getattr(self.get_queryset(), name)(*args, **kwargs)
           ~~~~~~~~~~~~~~~~~~~~~~~~~~~~~~~~~~^^^^^^^^^^^^^^^^^
  File "C:\Users\Gonzalo\Desktop\punto_fitness\env\Lib\site-packages\django\db\models\query.py", line 663, in create
    obj.save(force_insert=True, using=self.db)
    ~~~~~~~~^^^^^^^^^^^^^^^^^^^^^^^^^^^^^^^^^^
  File "C:\Users\Gonzalo\Desktop\punto_fitness\punto_fitness\punto_app\models.py", line 215, in save
    super().save(*args, **kwargs)
    ~~~~~~~~~~~~^^^^^^^^^^^^^^^^^
  File "C:\Users\Gonzalo\Desktop\punto_fitness\env\Lib\site-packages\django\db\models\base.py", line 902, in save
    self.save_base(
    ~~~~~~~~~~~~~~^
        using=using,
        ^^^^^^^^^^^^
    ...<2 lines>...
        update_fields=update_fields,
        ^^^^^^^^^^^^^^^^^^^^^^^^^^^^
    )
    ^
  File "C:\Users\Gonzalo\Desktop\punto_fitness\env\Lib\site-packages\django\db\models\base.py", line 1008, in save_base
    updated = self._save_table(
        raw,
    ...<4 lines>...
        update_fields,
    )
  File "C:\Users\Gonzalo\Desktop\punto_fitness\env\Lib\site-packages\django\db\models\base.py", line 1169, in _save_table
    results = self._do_insert(
        cls._base_manager, using, fields, returning_fields, raw
    )
  File "C:\Users\Gonzalo\Desktop\punto_fitness\env\Lib\site-packages\django\db\models\base.py", line 1210, in _do_insert
    return manager._insert(
           ~~~~~~~~~~~~~~~^
        [self],
        ^^^^^^^
    ...<3 lines>...
        raw=raw,
        ^^^^^^^^
    )
    ^
  File "C:\Users\Gonzalo\Desktop\punto_fitness\env\Lib\site-packages\django\db\models\manager.py", line 87, in manager_method
    return getattr(self.get_queryset(), name)(*args, **kwargs)
           ~~~~~~~~~~~~~~~~~~~~~~~~~~~~~~~~~~^^^^^^^^^^^^^^^^^
  File "C:\Users\Gonzalo\Desktop\punto_fitness\env\Lib\site-packages\django\db\models\query.py", line 1868, in _insert
    return query.get_compiler(using=using).execute_sql(returning_fields)
           ~~~~~~~~~~~~~~~~~~~~~~~~~~~~~~~~~~~~~~~~~~~^^^^^^^^^^^^^^^^^^
  File "C:\Users\Gonzalo\Desktop\punto_fitness\env\Lib\site-packages\django\db\models\sql\compiler.py", line 1882, in execute_sql
    cursor.execute(sql, params)
    ~~~~~~~~~~~~~~^^^^^^^^^^^^^
  File "C:\Users\Gonzalo\Desktop\punto_fitness\env\Lib\site-packages\django\db\backends\utils.py", line 122, in execute
    return super().execute(sql, params)
           ~~~~~~~~~~~~~~~^^^^^^^^^^^^^
  File "C:\Users\Gonzalo\Desktop\punto_fitness\env\Lib\site-packages\django\db\backends\utils.py", line 79, in execute
    return self._execute_with_wrappers(
           ~~~~~~~~~~~~~~~~~~~~~~~~~~~^
        sql, params, many=False, executor=self._execute
        ^^^^^^^^^^^^^^^^^^^^^^^^^^^^^^^^^^^^^^^^^^^^^^^
    )
    ^
  File "C:\Users\Gonzalo\Desktop\punto_fitness\env\Lib\site-packages\django\db\backends\utils.py", line 92, in _execute_with_wrappers
    return executor(sql, params, many, context)
  File "C:\Users\Gonzalo\Desktop\punto_fitness\env\Lib\site-packages\django\db\backends\utils.py", line 100, in _execute
    with self.db.wrap_database_errors:
         ^^^^^^^^^^^^^^^^^^^^^^^^^^^^
  File "C:\Users\Gonzalo\Desktop\punto_fitness\env\Lib\site-packages\django\db\utils.py", line 91, in __exit__
    raise dj_exc_value.with_traceback(traceback) from exc_value
  File "C:\Users\Gonzalo\Desktop\punto_fitness\env\Lib\site-packages\django\db\backends\utils.py", line 105, in _execute
    return self.cursor.execute(sql, params)
           ~~~~~~~~~~~~~~~~~~~^^^^^^^^^^^^^
django.db.utils.IntegrityError: llave duplicada viola restricción de unicidad «inscripcion_usuario_id_curso_id_fecha_realizacion_fb7ade3f_uniq»
DETAIL:  Ya existe la llave (usuario_id, curso_id, fecha_realizacion)=(4, 3, 2025-06-11).

ERROR 2025-06-09 01:29:49,356 basehttp 1188 3048 "POST /inscribir_curso/ HTTP/1.1" 500 157630
ERROR 2025-06-09 01:31:27,888 log 6436 11456 Internal Server Error: /inscribir_curso/
Traceback (most recent call last):
  File "C:\Users\Gonzalo\Desktop\punto_fitness\env\Lib\site-packages\django\db\backends\utils.py", line 105, in _execute
    return self.cursor.execute(sql, params)
           ~~~~~~~~~~~~~~~~~~~^^^^^^^^^^^^^
psycopg2.errors.UniqueViolation: llave duplicada viola restricción de unicidad «inscripcion_usuario_id_curso_id_fecha_realizacion_fb7ade3f_uniq»
DETAIL:  Ya existe la llave (usuario_id, curso_id, fecha_realizacion)=(4, 3, 2025-06-11).


The above exception was the direct cause of the following exception:

Traceback (most recent call last):
  File "C:\Users\Gonzalo\Desktop\punto_fitness\env\Lib\site-packages\django\core\handlers\exception.py", line 55, in inner
    response = get_response(request)
  File "C:\Users\Gonzalo\Desktop\punto_fitness\env\Lib\site-packages\django\core\handlers\base.py", line 197, in _get_response
    response = wrapped_callback(request, *callback_args, **callback_kwargs)
  File "C:\Users\Gonzalo\Desktop\punto_fitness\punto_fitness\punto_app\views.py", line 433, in inscribir_curso
    inscripcion = Inscripcion.objects.create(
        usuario_id=data['usuario_id'],
        curso_id=data['curso_id'],
        fecha_inscripcion=timezone.now()
    )
  File "C:\Users\Gonzalo\Desktop\punto_fitness\env\Lib\site-packages\django\db\models\manager.py", line 87, in manager_method
    return getattr(self.get_queryset(), name)(*args, **kwargs)
           ~~~~~~~~~~~~~~~~~~~~~~~~~~~~~~~~~~^^^^^^^^^^^^^^^^^
  File "C:\Users\Gonzalo\Desktop\punto_fitness\env\Lib\site-packages\django\db\models\query.py", line 663, in create
    obj.save(force_insert=True, using=self.db)
    ~~~~~~~~^^^^^^^^^^^^^^^^^^^^^^^^^^^^^^^^^^
  File "C:\Users\Gonzalo\Desktop\punto_fitness\punto_fitness\punto_app\models.py", line 215, in save
    super().save(*args, **kwargs)
    ~~~~~~~~~~~~^^^^^^^^^^^^^^^^^
  File "C:\Users\Gonzalo\Desktop\punto_fitness\env\Lib\site-packages\django\db\models\base.py", line 902, in save
    self.save_base(
    ~~~~~~~~~~~~~~^
        using=using,
        ^^^^^^^^^^^^
    ...<2 lines>...
        update_fields=update_fields,
        ^^^^^^^^^^^^^^^^^^^^^^^^^^^^
    )
    ^
  File "C:\Users\Gonzalo\Desktop\punto_fitness\env\Lib\site-packages\django\db\models\base.py", line 1008, in save_base
    updated = self._save_table(
        raw,
    ...<4 lines>...
        update_fields,
    )
  File "C:\Users\Gonzalo\Desktop\punto_fitness\env\Lib\site-packages\django\db\models\base.py", line 1169, in _save_table
    results = self._do_insert(
        cls._base_manager, using, fields, returning_fields, raw
    )
  File "C:\Users\Gonzalo\Desktop\punto_fitness\env\Lib\site-packages\django\db\models\base.py", line 1210, in _do_insert
    return manager._insert(
           ~~~~~~~~~~~~~~~^
        [self],
        ^^^^^^^
    ...<3 lines>...
        raw=raw,
        ^^^^^^^^
    )
    ^
  File "C:\Users\Gonzalo\Desktop\punto_fitness\env\Lib\site-packages\django\db\models\manager.py", line 87, in manager_method
    return getattr(self.get_queryset(), name)(*args, **kwargs)
           ~~~~~~~~~~~~~~~~~~~~~~~~~~~~~~~~~~^^^^^^^^^^^^^^^^^
  File "C:\Users\Gonzalo\Desktop\punto_fitness\env\Lib\site-packages\django\db\models\query.py", line 1868, in _insert
    return query.get_compiler(using=using).execute_sql(returning_fields)
           ~~~~~~~~~~~~~~~~~~~~~~~~~~~~~~~~~~~~~~~~~~~^^^^^^^^^^^^^^^^^^
  File "C:\Users\Gonzalo\Desktop\punto_fitness\env\Lib\site-packages\django\db\models\sql\compiler.py", line 1882, in execute_sql
    cursor.execute(sql, params)
    ~~~~~~~~~~~~~~^^^^^^^^^^^^^
  File "C:\Users\Gonzalo\Desktop\punto_fitness\env\Lib\site-packages\django\db\backends\utils.py", line 122, in execute
    return super().execute(sql, params)
           ~~~~~~~~~~~~~~~^^^^^^^^^^^^^
  File "C:\Users\Gonzalo\Desktop\punto_fitness\env\Lib\site-packages\django\db\backends\utils.py", line 79, in execute
    return self._execute_with_wrappers(
           ~~~~~~~~~~~~~~~~~~~~~~~~~~~^
        sql, params, many=False, executor=self._execute
        ^^^^^^^^^^^^^^^^^^^^^^^^^^^^^^^^^^^^^^^^^^^^^^^
    )
    ^
  File "C:\Users\Gonzalo\Desktop\punto_fitness\env\Lib\site-packages\django\db\backends\utils.py", line 92, in _execute_with_wrappers
    return executor(sql, params, many, context)
  File "C:\Users\Gonzalo\Desktop\punto_fitness\env\Lib\site-packages\django\db\backends\utils.py", line 100, in _execute
    with self.db.wrap_database_errors:
         ^^^^^^^^^^^^^^^^^^^^^^^^^^^^
  File "C:\Users\Gonzalo\Desktop\punto_fitness\env\Lib\site-packages\django\db\utils.py", line 91, in __exit__
    raise dj_exc_value.with_traceback(traceback) from exc_value
  File "C:\Users\Gonzalo\Desktop\punto_fitness\env\Lib\site-packages\django\db\backends\utils.py", line 105, in _execute
    return self.cursor.execute(sql, params)
           ~~~~~~~~~~~~~~~~~~~^^^^^^^^^^^^^
django.db.utils.IntegrityError: llave duplicada viola restricción de unicidad «inscripcion_usuario_id_curso_id_fecha_realizacion_fb7ade3f_uniq»
DETAIL:  Ya existe la llave (usuario_id, curso_id, fecha_realizacion)=(4, 3, 2025-06-11).

ERROR 2025-06-09 01:31:27,899 basehttp 6436 11456 "POST /inscribir_curso/ HTTP/1.1" 500 157630
ERROR 2025-06-09 01:33:35,544 log 2152 6824 Internal Server Error: /inscribir_curso/
Traceback (most recent call last):
  File "C:\Users\Gonzalo\Desktop\punto_fitness\env\Lib\site-packages\django\db\backends\utils.py", line 105, in _execute
    return self.cursor.execute(sql, params)
           ~~~~~~~~~~~~~~~~~~~^^^^^^^^^^^^^
psycopg2.errors.UniqueViolation: llave duplicada viola restricción de unicidad «inscripcion_usuario_id_curso_id_fecha_realizacion_fb7ade3f_uniq»
DETAIL:  Ya existe la llave (usuario_id, curso_id, fecha_realizacion)=(4, 3, 2025-06-11).


The above exception was the direct cause of the following exception:

Traceback (most recent call last):
  File "C:\Users\Gonzalo\Desktop\punto_fitness\env\Lib\site-packages\django\core\handlers\exception.py", line 55, in inner
    response = get_response(request)
  File "C:\Users\Gonzalo\Desktop\punto_fitness\env\Lib\site-packages\django\core\handlers\base.py", line 197, in _get_response
    response = wrapped_callback(request, *callback_args, **callback_kwargs)
  File "C:\Users\Gonzalo\Desktop\punto_fitness\punto_fitness\punto_app\views.py", line 433, in inscribir_curso
    inscripcion = Inscripcion.objects.create(
        usuario_id=data['usuario_id'],
        curso_id=data['curso_id'],
        fecha_inscripcion=timezone.now()
    )
  File "C:\Users\Gonzalo\Desktop\punto_fitness\env\Lib\site-packages\django\db\models\manager.py", line 87, in manager_method
    return getattr(self.get_queryset(), name)(*args, **kwargs)
           ~~~~~~~~~~~~~~~~~~~~~~~~~~~~~~~~~~^^^^^^^^^^^^^^^^^
  File "C:\Users\Gonzalo\Desktop\punto_fitness\env\Lib\site-packages\django\db\models\query.py", line 663, in create
    obj.save(force_insert=True, using=self.db)
    ~~~~~~~~^^^^^^^^^^^^^^^^^^^^^^^^^^^^^^^^^^
  File "C:\Users\Gonzalo\Desktop\punto_fitness\punto_fitness\punto_app\models.py", line 215, in save
    super().save(*args, **kwargs)
    ~~~~~~~~~~~~^^^^^^^^^^^^^^^^^
  File "C:\Users\Gonzalo\Desktop\punto_fitness\env\Lib\site-packages\django\db\models\base.py", line 902, in save
    self.save_base(
    ~~~~~~~~~~~~~~^
        using=using,
        ^^^^^^^^^^^^
    ...<2 lines>...
        update_fields=update_fields,
        ^^^^^^^^^^^^^^^^^^^^^^^^^^^^
    )
    ^
  File "C:\Users\Gonzalo\Desktop\punto_fitness\env\Lib\site-packages\django\db\models\base.py", line 1008, in save_base
    updated = self._save_table(
        raw,
    ...<4 lines>...
        update_fields,
    )
  File "C:\Users\Gonzalo\Desktop\punto_fitness\env\Lib\site-packages\django\db\models\base.py", line 1169, in _save_table
    results = self._do_insert(
        cls._base_manager, using, fields, returning_fields, raw
    )
  File "C:\Users\Gonzalo\Desktop\punto_fitness\env\Lib\site-packages\django\db\models\base.py", line 1210, in _do_insert
    return manager._insert(
           ~~~~~~~~~~~~~~~^
        [self],
        ^^^^^^^
    ...<3 lines>...
        raw=raw,
        ^^^^^^^^
    )
    ^
  File "C:\Users\Gonzalo\Desktop\punto_fitness\env\Lib\site-packages\django\db\models\manager.py", line 87, in manager_method
    return getattr(self.get_queryset(), name)(*args, **kwargs)
           ~~~~~~~~~~~~~~~~~~~~~~~~~~~~~~~~~~^^^^^^^^^^^^^^^^^
  File "C:\Users\Gonzalo\Desktop\punto_fitness\env\Lib\site-packages\django\db\models\query.py", line 1868, in _insert
    return query.get_compiler(using=using).execute_sql(returning_fields)
           ~~~~~~~~~~~~~~~~~~~~~~~~~~~~~~~~~~~~~~~~~~~^^^^^^^^^^^^^^^^^^
  File "C:\Users\Gonzalo\Desktop\punto_fitness\env\Lib\site-packages\django\db\models\sql\compiler.py", line 1882, in execute_sql
    cursor.execute(sql, params)
    ~~~~~~~~~~~~~~^^^^^^^^^^^^^
  File "C:\Users\Gonzalo\Desktop\punto_fitness\env\Lib\site-packages\django\db\backends\utils.py", line 122, in execute
    return super().execute(sql, params)
           ~~~~~~~~~~~~~~~^^^^^^^^^^^^^
  File "C:\Users\Gonzalo\Desktop\punto_fitness\env\Lib\site-packages\django\db\backends\utils.py", line 79, in execute
    return self._execute_with_wrappers(
           ~~~~~~~~~~~~~~~~~~~~~~~~~~~^
        sql, params, many=False, executor=self._execute
        ^^^^^^^^^^^^^^^^^^^^^^^^^^^^^^^^^^^^^^^^^^^^^^^
    )
    ^
  File "C:\Users\Gonzalo\Desktop\punto_fitness\env\Lib\site-packages\django\db\backends\utils.py", line 92, in _execute_with_wrappers
    return executor(sql, params, many, context)
  File "C:\Users\Gonzalo\Desktop\punto_fitness\env\Lib\site-packages\django\db\backends\utils.py", line 100, in _execute
    with self.db.wrap_database_errors:
         ^^^^^^^^^^^^^^^^^^^^^^^^^^^^
  File "C:\Users\Gonzalo\Desktop\punto_fitness\env\Lib\site-packages\django\db\utils.py", line 91, in __exit__
    raise dj_exc_value.with_traceback(traceback) from exc_value
  File "C:\Users\Gonzalo\Desktop\punto_fitness\env\Lib\site-packages\django\db\backends\utils.py", line 105, in _execute
    return self.cursor.execute(sql, params)
           ~~~~~~~~~~~~~~~~~~~^^^^^^^^^^^^^
django.db.utils.IntegrityError: llave duplicada viola restricción de unicidad «inscripcion_usuario_id_curso_id_fecha_realizacion_fb7ade3f_uniq»
DETAIL:  Ya existe la llave (usuario_id, curso_id, fecha_realizacion)=(4, 3, 2025-06-11).

ERROR 2025-06-09 01:33:35,556 basehttp 2152 6824 "POST /inscribir_curso/ HTTP/1.1" 500 157630
ERROR 2025-06-09 13:49:16,161 log 13980 7508 Internal Server Error: /
Traceback (most recent call last):
  File "C:\Users\Gonzalo\Desktop\punto_fitness\env\Lib\site-packages\django\template\base.py", line 510, in parse
    compile_func = self.tags[command]
                   ~~~~~~~~~^^^^^^^^^
KeyError: "'principal'"

During handling of the above exception, another exception occurred:

Traceback (most recent call last):
  File "C:\Users\Gonzalo\Desktop\punto_fitness\env\Lib\site-packages\django\core\handlers\exception.py", line 55, in inner
    response = get_response(request)
  File "C:\Users\Gonzalo\Desktop\punto_fitness\env\Lib\site-packages\django\core\handlers\base.py", line 197, in _get_response
    response = wrapped_callback(request, *callback_args, **callback_kwargs)
  File "C:\Users\Gonzalo\Desktop\punto_fitness\punto_fitness\punto_app\views.py", line 23, in principal
    return render(request, 'punto_app/principal.html')
  File "C:\Users\Gonzalo\Desktop\punto_fitness\env\Lib\site-packages\django\shortcuts.py", line 25, in render
    content = loader.render_to_string(template_name, context, request, using=using)
  File "C:\Users\Gonzalo\Desktop\punto_fitness\env\Lib\site-packages\django\template\loader.py", line 62, in render_to_string
    return template.render(context, request)
           ~~~~~~~~~~~~~~~^^^^^^^^^^^^^^^^^^
  File "C:\Users\Gonzalo\Desktop\punto_fitness\env\Lib\site-packages\django\template\backends\django.py", line 107, in render
    return self.template.render(context)
           ~~~~~~~~~~~~~~~~~~~~^^^^^^^^^
  File "C:\Users\Gonzalo\Desktop\punto_fitness\env\Lib\site-packages\django\template\base.py", line 171, in render
    return self._render(context)
           ~~~~~~~~~~~~^^^^^^^^^
  File "C:\Users\Gonzalo\Desktop\punto_fitness\env\Lib\site-packages\django\template\base.py", line 163, in _render
    return self.nodelist.render(context)
           ~~~~~~~~~~~~~~~~~~~~^^^^^^^^^
  File "C:\Users\Gonzalo\Desktop\punto_fitness\env\Lib\site-packages\django\template\base.py", line 1016, in render
    return SafeString("".join([node.render_annotated(context) for node in self]))
                               ~~~~~~~~~~~~~~~~~~~~~^^^^^^^^^
  File "C:\Users\Gonzalo\Desktop\punto_fitness\env\Lib\site-packages\django\template\base.py", line 977, in render_annotated
    return self.render(context)
           ~~~~~~~~~~~^^^^^^^^^
  File "C:\Users\Gonzalo\Desktop\punto_fitness\env\Lib\site-packages\django\template\loader_tags.py", line 134, in render
    compiled_parent = self.get_parent(context)
  File "C:\Users\Gonzalo\Desktop\punto_fitness\env\Lib\site-packages\django\template\loader_tags.py", line 131, in get_parent
    return self.find_template(parent, context)
           ~~~~~~~~~~~~~~~~~~^^^^^^^^^^^^^^^^^
  File "C:\Users\Gonzalo\Desktop\punto_fitness\env\Lib\site-packages\django\template\loader_tags.py", line 109, in find_template
    template, origin = context.template.engine.find_template(
                       ~~~~~~~~~~~~~~~~~~~~~~~~~~~~~~~~~~~~~^
        template_name,
        ^^^^^^^^^^^^^^
        skip=history,
        ^^^^^^^^^^^^^
    )
    ^
  File "C:\Users\Gonzalo\Desktop\punto_fitness\env\Lib\site-packages\django\template\engine.py", line 159, in find_template
    template = loader.get_template(name, skip=skip)
  File "C:\Users\Gonzalo\Desktop\punto_fitness\env\Lib\site-packages\django\template\loaders\cached.py", line 57, in get_template
    template = super().get_template(template_name, skip)
  File "C:\Users\Gonzalo\Desktop\punto_fitness\env\Lib\site-packages\django\template\loaders\base.py", line 28, in get_template
    return Template(
        contents,
    ...<2 lines>...
        self.engine,
    )
  File "C:\Users\Gonzalo\Desktop\punto_fitness\env\Lib\site-packages\django\template\base.py", line 154, in __init__
    self.nodelist = self.compile_nodelist()
                    ~~~~~~~~~~~~~~~~~~~~~^^
  File "C:\Users\Gonzalo\Desktop\punto_fitness\env\Lib\site-packages\django\template\base.py", line 196, in compile_nodelist
    nodelist = parser.parse()
  File "C:\Users\Gonzalo\Desktop\punto_fitness\env\Lib\site-packages\django\template\base.py", line 512, in parse
    self.invalid_block_tag(token, command, parse_until)
    ~~~~~~~~~~~~~~~~~~~~~~^^^^^^^^^^^^^^^^^^^^^^^^^^^^^
  File "C:\Users\Gonzalo\Desktop\punto_fitness\env\Lib\site-packages\django\template\base.py", line 577, in invalid_block_tag
    raise self.error(
    ...<3 lines>...
    )
django.template.exceptions.TemplateSyntaxError: Invalid block tag on line 26: ''principal''. Did you forget to register or load this tag?
ERROR 2025-06-09 13:49:16,179 basehttp 13980 7508 "GET / HTTP/1.1" 500 188014
ERROR 2025-06-11 23:57:30,764 exception 9348 17152 Invalid HTTP_HOST header: 'testserver'. You may need to add 'testserver' to ALLOWED_HOSTS.
Traceback (most recent call last):
  File "C:\Users\Gonzalo\Desktop\punto_fitness\env\Lib\site-packages\django\core\handlers\exception.py", line 55, in inner
    response = get_response(request)
  File "C:\Users\Gonzalo\Desktop\punto_fitness\env\Lib\site-packages\django\utils\deprecation.py", line 119, in __call__
    response = self.process_request(request)
  File "C:\Users\Gonzalo\Desktop\punto_fitness\env\Lib\site-packages\django\middleware\common.py", line 48, in process_request
    host = request.get_host()
  File "C:\Users\Gonzalo\Desktop\punto_fitness\env\Lib\site-packages\django\http\request.py", line 191, in get_host
    raise DisallowedHost(msg)
django.core.exceptions.DisallowedHost: Invalid HTTP_HOST header: 'testserver'. You may need to add 'testserver' to ALLOWED_HOSTS.
ERROR 2025-06-12 00:01:27,329 log 17348 14276 Internal Server Error: /enviar-codigo-verificacion/
ERROR 2025-06-12 00:01:27,330 basehttp 17348 14276 "POST /enviar-codigo-verificacion/ HTTP/1.1" 500 39
ERROR 2025-06-12 00:26:02,638 log 7336 13364 Internal Server Error: /registro/
ERROR 2025-06-12 00:26:02,643 basehttp 7336 13364 "POST /registro/ HTTP/1.1" 500 38
ERROR 2025-06-29 22:35:28,404 log 8080 15940 Internal Server Error: /verificar-sesion/
Traceback (most recent call last):
  File "C:\Users\Gonzalo\AppData\Roaming\Python\Python313\site-packages\django\db\backends\utils.py", line 105, in _execute
    return self.cursor.execute(sql, params)
           ~~~~~~~~~~~~~~~~~~~^^^^^^^^^^^^^
psycopg2.errors.UndefinedTable: no existe la relación «cliente»
LINE 1: ...liente"."fecha_registro", "cliente"."estado" FROM "cliente" ...
                                                             ^


The above exception was the direct cause of the following exception:

Traceback (most recent call last):
  File "C:\Users\Gonzalo\AppData\Roaming\Python\Python313\site-packages\django\core\handlers\exception.py", line 55, in inner
    response = get_response(request)
  File "C:\Users\Gonzalo\AppData\Roaming\Python\Python313\site-packages\django\core\handlers\base.py", line 197, in _get_response
    response = wrapped_callback(request, *callback_args, **callback_kwargs)
  File "C:\Users\Gonzalo\AppData\Roaming\Python\Python313\site-packages\django\views\decorators\csrf.py", line 65, in _view_wrapper
    return view_func(request, *args, **kwargs)
  File "C:\Users\Gonzalo\Desktop\Taller Ing. Software\punto_fitness\punto_fitness\punto_app\views.py", line 1395, in verificar_sesion
    cliente = Cliente.objects.get(id=cliente_id)
  File "C:\Users\Gonzalo\AppData\Roaming\Python\Python313\site-packages\django\db\models\manager.py", line 87, in manager_method
    return getattr(self.get_queryset(), name)(*args, **kwargs)
           ~~~~~~~~~~~~~~~~~~~~~~~~~~~~~~~~~~^^^^^^^^^^^^^^^^^
  File "C:\Users\Gonzalo\AppData\Roaming\Python\Python313\site-packages\django\db\models\query.py", line 629, in get
    num = len(clone)
  File "C:\Users\Gonzalo\AppData\Roaming\Python\Python313\site-packages\django\db\models\query.py", line 366, in __len__
    self._fetch_all()
    ~~~~~~~~~~~~~~~^^
  File "C:\Users\Gonzalo\AppData\Roaming\Python\Python313\site-packages\django\db\models\query.py", line 1949, in _fetch_all
    self._result_cache = list(self._iterable_class(self))
                         ~~~~^^^^^^^^^^^^^^^^^^^^^^^^^^^^
  File "C:\Users\Gonzalo\AppData\Roaming\Python\Python313\site-packages\django\db\models\query.py", line 91, in __iter__
    results = compiler.execute_sql(
        chunked_fetch=self.chunked_fetch, chunk_size=self.chunk_size
    )
  File "C:\Users\Gonzalo\AppData\Roaming\Python\Python313\site-packages\django\db\models\sql\compiler.py", line 1623, in execute_sql
    cursor.execute(sql, params)
    ~~~~~~~~~~~~~~^^^^^^^^^^^^^
  File "C:\Users\Gonzalo\AppData\Roaming\Python\Python313\site-packages\django\db\backends\utils.py", line 122, in execute
    return super().execute(sql, params)
           ~~~~~~~~~~~~~~~^^^^^^^^^^^^^
  File "C:\Users\Gonzalo\AppData\Roaming\Python\Python313\site-packages\django\db\backends\utils.py", line 79, in execute
    return self._execute_with_wrappers(
           ~~~~~~~~~~~~~~~~~~~~~~~~~~~^
        sql, params, many=False, executor=self._execute
        ^^^^^^^^^^^^^^^^^^^^^^^^^^^^^^^^^^^^^^^^^^^^^^^
    )
    ^
  File "C:\Users\Gonzalo\AppData\Roaming\Python\Python313\site-packages\django\db\backends\utils.py", line 92, in _execute_with_wrappers
    return executor(sql, params, many, context)
  File "C:\Users\Gonzalo\AppData\Roaming\Python\Python313\site-packages\django\db\backends\utils.py", line 100, in _execute
    with self.db.wrap_database_errors:
         ^^^^^^^^^^^^^^^^^^^^^^^^^^^^
  File "C:\Users\Gonzalo\AppData\Roaming\Python\Python313\site-packages\django\db\utils.py", line 91, in __exit__
    raise dj_exc_value.with_traceback(traceback) from exc_value
  File "C:\Users\Gonzalo\AppData\Roaming\Python\Python313\site-packages\django\db\backends\utils.py", line 105, in _execute
    return self.cursor.execute(sql, params)
           ~~~~~~~~~~~~~~~~~~~^^^^^^^^^^^^^
django.db.utils.ProgrammingError: no existe la relación «cliente»
LINE 1: ...liente"."fecha_registro", "cliente"."estado" FROM "cliente" ...
                                                             ^

ERROR 2025-06-29 22:35:28,414 basehttp 8080 15940 "GET /verificar-sesion/ HTTP/1.1" 500 137688
ERROR 2025-06-29 22:36:29,305 log 8080 15940 Internal Server Error: /verificar-sesion/
Traceback (most recent call last):
  File "C:\Users\Gonzalo\AppData\Roaming\Python\Python313\site-packages\django\contrib\sessions\backends\base.py", line 244, in _get_session
    return self._session_cache
           ^^^^^^^^^^^^^^^^^^^
AttributeError: 'SessionStore' object has no attribute '_session_cache'

During handling of the above exception, another exception occurred:

Traceback (most recent call last):
  File "C:\Users\Gonzalo\AppData\Roaming\Python\Python313\site-packages\django\db\backends\utils.py", line 105, in _execute
    return self.cursor.execute(sql, params)
           ~~~~~~~~~~~~~~~~~~~^^^^^^^^^^^^^
psycopg2.errors.UndefinedTable: no existe la relación «django_session»
LINE 1: ...ession_data", "django_session"."expire_date" FROM "django_se...
                                                             ^


The above exception was the direct cause of the following exception:

Traceback (most recent call last):
  File "C:\Users\Gonzalo\AppData\Roaming\Python\Python313\site-packages\django\core\handlers\exception.py", line 55, in inner
    response = get_response(request)
  File "C:\Users\Gonzalo\AppData\Roaming\Python\Python313\site-packages\django\core\handlers\base.py", line 197, in _get_response
    response = wrapped_callback(request, *callback_args, **callback_kwargs)
  File "C:\Users\Gonzalo\AppData\Roaming\Python\Python313\site-packages\django\views\decorators\csrf.py", line 65, in _view_wrapper
    return view_func(request, *args, **kwargs)
  File "C:\Users\Gonzalo\Desktop\Taller Ing. Software\punto_fitness\punto_fitness\punto_app\views.py", line 1391, in verificar_sesion
    cliente_id = request.session.get('cliente_id')
  File "C:\Users\Gonzalo\AppData\Roaming\Python\Python313\site-packages\django\contrib\sessions\backends\base.py", line 74, in get
    return self._session.get(key, default)
           ^^^^^^^^^^^^^
  File "C:\Users\Gonzalo\AppData\Roaming\Python\Python313\site-packages\django\contrib\sessions\backends\base.py", line 249, in _get_session
    self._session_cache = self.load()
                          ~~~~~~~~~^^
  File "C:\Users\Gonzalo\AppData\Roaming\Python\Python313\site-packages\django\contrib\sessions\backends\db.py", line 55, in load
    s = self._get_session_from_db()
  File "C:\Users\Gonzalo\AppData\Roaming\Python\Python313\site-packages\django\contrib\sessions\backends\db.py", line 34, in _get_session_from_db
    return self.model.objects.get(
           ~~~~~~~~~~~~~~~~~~~~~~^
        session_key=self.session_key, expire_date__gt=timezone.now()
        ^^^^^^^^^^^^^^^^^^^^^^^^^^^^^^^^^^^^^^^^^^^^^^^^^^^^^^^^^^^^
    )
    ^
  File "C:\Users\Gonzalo\AppData\Roaming\Python\Python313\site-packages\django\db\models\manager.py", line 87, in manager_method
    return getattr(self.get_queryset(), name)(*args, **kwargs)
           ~~~~~~~~~~~~~~~~~~~~~~~~~~~~~~~~~~^^^^^^^^^^^^^^^^^
  File "C:\Users\Gonzalo\AppData\Roaming\Python\Python313\site-packages\django\db\models\query.py", line 629, in get
    num = len(clone)
  File "C:\Users\Gonzalo\AppData\Roaming\Python\Python313\site-packages\django\db\models\query.py", line 366, in __len__
    self._fetch_all()
    ~~~~~~~~~~~~~~~^^
  File "C:\Users\Gonzalo\AppData\Roaming\Python\Python313\site-packages\django\db\models\query.py", line 1949, in _fetch_all
    self._result_cache = list(self._iterable_class(self))
                         ~~~~^^^^^^^^^^^^^^^^^^^^^^^^^^^^
  File "C:\Users\Gonzalo\AppData\Roaming\Python\Python313\site-packages\django\db\models\query.py", line 91, in __iter__
    results = compiler.execute_sql(
        chunked_fetch=self.chunked_fetch, chunk_size=self.chunk_size
    )
  File "C:\Users\Gonzalo\AppData\Roaming\Python\Python313\site-packages\django\db\models\sql\compiler.py", line 1623, in execute_sql
    cursor.execute(sql, params)
    ~~~~~~~~~~~~~~^^^^^^^^^^^^^
  File "C:\Users\Gonzalo\AppData\Roaming\Python\Python313\site-packages\django\db\backends\utils.py", line 122, in execute
    return super().execute(sql, params)
           ~~~~~~~~~~~~~~~^^^^^^^^^^^^^
  File "C:\Users\Gonzalo\AppData\Roaming\Python\Python313\site-packages\django\db\backends\utils.py", line 79, in execute
    return self._execute_with_wrappers(
           ~~~~~~~~~~~~~~~~~~~~~~~~~~~^
        sql, params, many=False, executor=self._execute
        ^^^^^^^^^^^^^^^^^^^^^^^^^^^^^^^^^^^^^^^^^^^^^^^
    )
    ^
  File "C:\Users\Gonzalo\AppData\Roaming\Python\Python313\site-packages\django\db\backends\utils.py", line 92, in _execute_with_wrappers
    return executor(sql, params, many, context)
  File "C:\Users\Gonzalo\AppData\Roaming\Python\Python313\site-packages\django\db\backends\utils.py", line 100, in _execute
    with self.db.wrap_database_errors:
         ^^^^^^^^^^^^^^^^^^^^^^^^^^^^
  File "C:\Users\Gonzalo\AppData\Roaming\Python\Python313\site-packages\django\db\utils.py", line 91, in __exit__
    raise dj_exc_value.with_traceback(traceback) from exc_value
  File "C:\Users\Gonzalo\AppData\Roaming\Python\Python313\site-packages\django\db\backends\utils.py", line 105, in _execute
    return self.cursor.execute(sql, params)
           ~~~~~~~~~~~~~~~~~~~^^^^^^^^^^^^^
django.db.utils.ProgrammingError: no existe la relación «django_session»
LINE 1: ...ession_data", "django_session"."expire_date" FROM "django_se...
                                                             ^

ERROR 2025-06-29 22:36:29,316 basehttp 8080 15940 "GET /verificar-sesion/ HTTP/1.1" 500 157844
ERROR 2025-06-29 23:25:35,391 log 4524 15584 Internal Server Error: /venta_producto/
Traceback (most recent call last):
  File "C:\Users\Gonzalo\AppData\Roaming\Python\Python313\site-packages\django\core\handlers\exception.py", line 55, in inner
    response = get_response(request)
  File "C:\Users\Gonzalo\AppData\Roaming\Python\Python313\site-packages\django\core\handlers\base.py", line 197, in _get_response
    response = wrapped_callback(request, *callback_args, **callback_kwargs)
  File "C:\Users\Gonzalo\Desktop\Taller Ing. Software\punto_fitness\punto_fitness\punto_app\views.py", line 2242, in venta_producto
    return render(request, 'punto_app/ventaproducto.html',{'productos': productos,'categorias': categorias})
  File "C:\Users\Gonzalo\AppData\Roaming\Python\Python313\site-packages\django\shortcuts.py", line 25, in render
    content = loader.render_to_string(template_name, context, request, using=using)
  File "C:\Users\Gonzalo\AppData\Roaming\Python\Python313\site-packages\django\template\loader.py", line 61, in render_to_string
    template = get_template(template_name, using=using)
  File "C:\Users\Gonzalo\AppData\Roaming\Python\Python313\site-packages\django\template\loader.py", line 19, in get_template
    raise TemplateDoesNotExist(template_name, chain=chain)
django.template.exceptions.TemplateDoesNotExist: punto_app/ventaproducto.html
ERROR 2025-06-29 23:25:35,396 basehttp 4524 15584 "GET /venta_producto/ HTTP/1.1" 500 86018
ERROR 2025-06-29 23:43:22,612 log 1220 11412 Internal Server Error: /venta_confirmada/
ERROR 2025-06-29 23:43:22,613 basehttp 1220 11412 "POST /venta_confirmada/ HTTP/1.1" 500 135
ERROR 2025-06-29 23:43:55,787 log 1220 11412 Internal Server Error: /venta_confirmada/
ERROR 2025-06-29 23:43:55,787 basehttp 1220 11412 "POST /venta_confirmada/ HTTP/1.1" 500 135
ERROR 2025-06-29 23:44:02,259 log 1220 11412 Internal Server Error: /venta_confirmada/
ERROR 2025-06-29 23:44:02,260 basehttp 1220 11412 "POST /venta_confirmada/ HTTP/1.1" 500 135
ERROR 2025-06-29 23:44:03,523 log 1220 11412 Internal Server Error: /venta_confirmada/
ERROR 2025-06-29 23:44:03,523 basehttp 1220 11412 "POST /venta_confirmada/ HTTP/1.1" 500 135
ERROR 2025-06-29 23:44:04,443 log 1220 11412 Internal Server Error: /venta_confirmada/
ERROR 2025-06-29 23:44:04,444 basehttp 1220 11412 "POST /venta_confirmada/ HTTP/1.1" 500 135
ERROR 2025-06-29 23:44:41,473 log 1220 11412 Internal Server Error: /venta_confirmada/
ERROR 2025-06-29 23:44:41,474 basehttp 1220 11412 "POST /venta_confirmada/ HTTP/1.1" 500 135
ERROR 2025-06-29 23:44:42,518 log 1220 11412 Internal Server Error: /venta_confirmada/
ERROR 2025-06-29 23:44:42,518 basehttp 1220 11412 "POST /venta_confirmada/ HTTP/1.1" 500 135
ERROR 2025-06-29 23:44:43,505 log 1220 11412 Internal Server Error: /venta_confirmada/
ERROR 2025-06-29 23:44:43,506 basehttp 1220 11412 "POST /venta_confirmada/ HTTP/1.1" 500 135
ERROR 2025-06-29 23:44:44,414 log 1220 11412 Internal Server Error: /venta_confirmada/
ERROR 2025-06-29 23:44:44,414 basehttp 1220 11412 "POST /venta_confirmada/ HTTP/1.1" 500 135
ERROR 2025-06-29 23:44:45,279 log 1220 11412 Internal Server Error: /venta_confirmada/
ERROR 2025-06-29 23:44:45,279 basehttp 1220 11412 "POST /venta_confirmada/ HTTP/1.1" 500 136
ERROR 2025-06-29 23:44:46,096 log 1220 11412 Internal Server Error: /venta_confirmada/
ERROR 2025-06-29 23:44:46,097 basehttp 1220 11412 "POST /venta_confirmada/ HTTP/1.1" 500 136
ERROR 2025-06-29 23:44:46,921 log 1220 11412 Internal Server Error: /venta_confirmada/
ERROR 2025-06-29 23:44:46,922 basehttp 1220 11412 "POST /venta_confirmada/ HTTP/1.1" 500 136
ERROR 2025-06-29 23:44:47,832 log 1220 11412 Internal Server Error: /venta_confirmada/
ERROR 2025-06-29 23:44:47,833 basehttp 1220 11412 "POST /venta_confirmada/ HTTP/1.1" 500 136
ERROR 2025-06-29 23:44:48,604 log 1220 11412 Internal Server Error: /venta_confirmada/
ERROR 2025-06-29 23:44:48,605 basehttp 1220 11412 "POST /venta_confirmada/ HTTP/1.1" 500 136
ERROR 2025-06-29 23:44:49,380 log 1220 11412 Internal Server Error: /venta_confirmada/
ERROR 2025-06-29 23:44:49,380 basehttp 1220 11412 "POST /venta_confirmada/ HTTP/1.1" 500 136
ERROR 2025-06-30 00:11:47,953 log 16544 9620 Internal Server Error: /membresias/
Traceback (most recent call last):
  File "C:\Users\Gonzalo\AppData\Roaming\Python\Python313\site-packages\django\core\handlers\exception.py", line 55, in inner
    response = get_response(request)
  File "C:\Users\Gonzalo\AppData\Roaming\Python\Python313\site-packages\django\core\handlers\base.py", line 197, in _get_response
    response = wrapped_callback(request, *callback_args, **callback_kwargs)
  File "C:\Users\Gonzalo\Desktop\Taller Ing. Software\punto_fitness\punto_fitness\punto_app\decorators.py", line 22, in _wrapped_view
    return view_func(request, *args, **kwargs)
  File "C:\Users\Gonzalo\Desktop\Taller Ing. Software\punto_fitness\punto_fitness\punto_app\views.py", line 2509, in membresias
    return render(request, 'punto_app/admin_membresias.html', {
        'membresias': membresias,
    ...<2 lines>...
        'clientes': clientes
    })
  File "C:\Users\Gonzalo\AppData\Roaming\Python\Python313\site-packages\django\shortcuts.py", line 25, in render
    content = loader.render_to_string(template_name, context, request, using=using)
  File "C:\Users\Gonzalo\AppData\Roaming\Python\Python313\site-packages\django\template\loader.py", line 61, in render_to_string
    template = get_template(template_name, using=using)
  File "C:\Users\Gonzalo\AppData\Roaming\Python\Python313\site-packages\django\template\loader.py", line 19, in get_template
    raise TemplateDoesNotExist(template_name, chain=chain)
django.template.exceptions.TemplateDoesNotExist: punto_app/admin_membresias.html
ERROR 2025-06-30 00:11:47,957 basehttp 16544 9620 "GET /membresias/ HTTP/1.1" 500 105009
ERROR 2025-06-30 23:41:59,443 log 16068 3964 Internal Server Error: /venta_producto/
Traceback (most recent call last):
  File "C:\Users\Gonzalo\AppData\Roaming\Python\Python313\site-packages\django\core\handlers\exception.py", line 55, in inner
    response = get_response(request)
  File "C:\Users\Gonzalo\AppData\Roaming\Python\Python313\site-packages\django\core\handlers\base.py", line 197, in _get_response
    response = wrapped_callback(request, *callback_args, **callback_kwargs)
  File "C:\Users\Gonzalo\Desktop\Taller Ing. Software\punto_fitness\punto_fitness\punto_app\views.py", line 2250, in venta_producto
    return render(request, 'punto_app/ventaproducto.html',{'productos': productos,'categorias': categorias})
  File "C:\Users\Gonzalo\AppData\Roaming\Python\Python313\site-packages\django\shortcuts.py", line 25, in render
    content = loader.render_to_string(template_name, context, request, using=using)
  File "C:\Users\Gonzalo\AppData\Roaming\Python\Python313\site-packages\django\template\loader.py", line 62, in render_to_string
    return template.render(context, request)
           ~~~~~~~~~~~~~~~^^^^^^^^^^^^^^^^^^
  File "C:\Users\Gonzalo\AppData\Roaming\Python\Python313\site-packages\django\template\backends\django.py", line 107, in render
    return self.template.render(context)
           ~~~~~~~~~~~~~~~~~~~~^^^^^^^^^
  File "C:\Users\Gonzalo\AppData\Roaming\Python\Python313\site-packages\django\template\base.py", line 171, in render
    return self._render(context)
           ~~~~~~~~~~~~^^^^^^^^^
  File "C:\Users\Gonzalo\AppData\Roaming\Python\Python313\site-packages\django\template\base.py", line 163, in _render
    return self.nodelist.render(context)
           ~~~~~~~~~~~~~~~~~~~~^^^^^^^^^
  File "C:\Users\Gonzalo\AppData\Roaming\Python\Python313\site-packages\django\template\base.py", line 1016, in render
    return SafeString("".join([node.render_annotated(context) for node in self]))
                               ~~~~~~~~~~~~~~~~~~~~~^^^^^^^^^
  File "C:\Users\Gonzalo\AppData\Roaming\Python\Python313\site-packages\django\template\base.py", line 977, in render_annotated
    return self.render(context)
           ~~~~~~~~~~~^^^^^^^^^
  File "C:\Users\Gonzalo\AppData\Roaming\Python\Python313\site-packages\django\template\loader_tags.py", line 134, in render
    compiled_parent = self.get_parent(context)
  File "C:\Users\Gonzalo\AppData\Roaming\Python\Python313\site-packages\django\template\loader_tags.py", line 131, in get_parent
    return self.find_template(parent, context)
           ~~~~~~~~~~~~~~~~~~^^^^^^^^^^^^^^^^^
  File "C:\Users\Gonzalo\AppData\Roaming\Python\Python313\site-packages\django\template\loader_tags.py", line 109, in find_template
    template, origin = context.template.engine.find_template(
                       ~~~~~~~~~~~~~~~~~~~~~~~~~~~~~~~~~~~~~^
        template_name,
        ^^^^^^^^^^^^^^
        skip=history,
        ^^^^^^^^^^^^^
    )
    ^
  File "C:\Users\Gonzalo\AppData\Roaming\Python\Python313\site-packages\django\template\engine.py", line 159, in find_template
    template = loader.get_template(name, skip=skip)
  File "C:\Users\Gonzalo\AppData\Roaming\Python\Python313\site-packages\django\template\loaders\cached.py", line 57, in get_template
    template = super().get_template(template_name, skip)
  File "C:\Users\Gonzalo\AppData\Roaming\Python\Python313\site-packages\django\template\loaders\base.py", line 28, in get_template
    return Template(
        contents,
    ...<2 lines>...
        self.engine,
    )
  File "C:\Users\Gonzalo\AppData\Roaming\Python\Python313\site-packages\django\template\base.py", line 154, in __init__
    self.nodelist = self.compile_nodelist()
                    ~~~~~~~~~~~~~~~~~~~~~^^
  File "C:\Users\Gonzalo\AppData\Roaming\Python\Python313\site-packages\django\template\base.py", line 196, in compile_nodelist
    nodelist = parser.parse()
  File "C:\Users\Gonzalo\AppData\Roaming\Python\Python313\site-packages\django\template\base.py", line 518, in parse
    raise self.error(token, e)
  File "C:\Users\Gonzalo\AppData\Roaming\Python\Python313\site-packages\django\template\base.py", line 516, in parse
    compiled_result = compile_func(self, token)
  File "C:\Users\Gonzalo\AppData\Roaming\Python\Python313\site-packages\django\template\loader_tags.py", line 228, in do_block
    raise TemplateSyntaxError(
        "'%s' tag with name '%s' appears more than once" % (bits[0], block_name)
    )
django.template.exceptions.TemplateSyntaxError: 'block' tag with name 'extra_head' appears more than once
ERROR 2025-06-30 23:41:59,453 basehttp 16068 3964 "GET /venta_producto/ HTTP/1.1" 500 205229
ERROR 2025-06-30 23:42:00,288 log 16068 3964 Internal Server Error: /venta_producto/
Traceback (most recent call last):
  File "C:\Users\Gonzalo\AppData\Roaming\Python\Python313\site-packages\django\core\handlers\exception.py", line 55, in inner
    response = get_response(request)
  File "C:\Users\Gonzalo\AppData\Roaming\Python\Python313\site-packages\django\core\handlers\base.py", line 197, in _get_response
    response = wrapped_callback(request, *callback_args, **callback_kwargs)
  File "C:\Users\Gonzalo\Desktop\Taller Ing. Software\punto_fitness\punto_fitness\punto_app\views.py", line 2250, in venta_producto
    return render(request, 'punto_app/ventaproducto.html',{'productos': productos,'categorias': categorias})
  File "C:\Users\Gonzalo\AppData\Roaming\Python\Python313\site-packages\django\shortcuts.py", line 25, in render
    content = loader.render_to_string(template_name, context, request, using=using)
  File "C:\Users\Gonzalo\AppData\Roaming\Python\Python313\site-packages\django\template\loader.py", line 62, in render_to_string
    return template.render(context, request)
           ~~~~~~~~~~~~~~~^^^^^^^^^^^^^^^^^^
  File "C:\Users\Gonzalo\AppData\Roaming\Python\Python313\site-packages\django\template\backends\django.py", line 107, in render
    return self.template.render(context)
           ~~~~~~~~~~~~~~~~~~~~^^^^^^^^^
  File "C:\Users\Gonzalo\AppData\Roaming\Python\Python313\site-packages\django\template\base.py", line 171, in render
    return self._render(context)
           ~~~~~~~~~~~~^^^^^^^^^
  File "C:\Users\Gonzalo\AppData\Roaming\Python\Python313\site-packages\django\template\base.py", line 163, in _render
    return self.nodelist.render(context)
           ~~~~~~~~~~~~~~~~~~~~^^^^^^^^^
  File "C:\Users\Gonzalo\AppData\Roaming\Python\Python313\site-packages\django\template\base.py", line 1016, in render
    return SafeString("".join([node.render_annotated(context) for node in self]))
                               ~~~~~~~~~~~~~~~~~~~~~^^^^^^^^^
  File "C:\Users\Gonzalo\AppData\Roaming\Python\Python313\site-packages\django\template\base.py", line 977, in render_annotated
    return self.render(context)
           ~~~~~~~~~~~^^^^^^^^^
  File "C:\Users\Gonzalo\AppData\Roaming\Python\Python313\site-packages\django\template\loader_tags.py", line 134, in render
    compiled_parent = self.get_parent(context)
  File "C:\Users\Gonzalo\AppData\Roaming\Python\Python313\site-packages\django\template\loader_tags.py", line 131, in get_parent
    return self.find_template(parent, context)
           ~~~~~~~~~~~~~~~~~~^^^^^^^^^^^^^^^^^
  File "C:\Users\Gonzalo\AppData\Roaming\Python\Python313\site-packages\django\template\loader_tags.py", line 109, in find_template
    template, origin = context.template.engine.find_template(
                       ~~~~~~~~~~~~~~~~~~~~~~~~~~~~~~~~~~~~~^
        template_name,
        ^^^^^^^^^^^^^^
        skip=history,
        ^^^^^^^^^^^^^
    )
    ^
  File "C:\Users\Gonzalo\AppData\Roaming\Python\Python313\site-packages\django\template\engine.py", line 159, in find_template
    template = loader.get_template(name, skip=skip)
  File "C:\Users\Gonzalo\AppData\Roaming\Python\Python313\site-packages\django\template\loaders\cached.py", line 57, in get_template
    template = super().get_template(template_name, skip)
  File "C:\Users\Gonzalo\AppData\Roaming\Python\Python313\site-packages\django\template\loaders\base.py", line 28, in get_template
    return Template(
        contents,
    ...<2 lines>...
        self.engine,
    )
  File "C:\Users\Gonzalo\AppData\Roaming\Python\Python313\site-packages\django\template\base.py", line 154, in __init__
    self.nodelist = self.compile_nodelist()
                    ~~~~~~~~~~~~~~~~~~~~~^^
  File "C:\Users\Gonzalo\AppData\Roaming\Python\Python313\site-packages\django\template\base.py", line 196, in compile_nodelist
    nodelist = parser.parse()
  File "C:\Users\Gonzalo\AppData\Roaming\Python\Python313\site-packages\django\template\base.py", line 518, in parse
    raise self.error(token, e)
  File "C:\Users\Gonzalo\AppData\Roaming\Python\Python313\site-packages\django\template\base.py", line 516, in parse
    compiled_result = compile_func(self, token)
  File "C:\Users\Gonzalo\AppData\Roaming\Python\Python313\site-packages\django\template\loader_tags.py", line 228, in do_block
    raise TemplateSyntaxError(
        "'%s' tag with name '%s' appears more than once" % (bits[0], block_name)
    )
django.template.exceptions.TemplateSyntaxError: 'block' tag with name 'extra_head' appears more than once
ERROR 2025-06-30 23:42:00,343 basehttp 16068 3964 "GET /venta_producto/ HTTP/1.1" 500 205229
ERROR 2025-07-01 23:36:41,786 log 13364 31904 Internal Server Error: /
Traceback (most recent call last):
  File "C:\Users\damia\AppData\Local\Programs\Python\Python313\Lib\site-packages\django\contrib\sessions\backends\base.py", line 244, in _get_session
    return self._session_cache
           ^^^^^^^^^^^^^^^^^^^
AttributeError: 'SessionStore' object has no attribute '_session_cache'

During handling of the above exception, another exception occurred:

Traceback (most recent call last):
  File "C:\Users\damia\AppData\Local\Programs\Python\Python313\Lib\site-packages\django\db\backends\utils.py", line 105, in _execute
    return self.cursor.execute(sql, params)
           ~~~~~~~~~~~~~~~~~~~^^^^^^^^^^^^^
psycopg2.errors.UndefinedTable: no existe la relación «django_session»
LINE 1: ...ession_data", "django_session"."expire_date" FROM "django_se...
                                                             ^


The above exception was the direct cause of the following exception:

Traceback (most recent call last):
  File "C:\Users\damia\AppData\Local\Programs\Python\Python313\Lib\site-packages\django\core\handlers\exception.py", line 55, in inner
    response = get_response(request)
  File "C:\Users\damia\AppData\Local\Programs\Python\Python313\Lib\site-packages\django\core\handlers\base.py", line 197, in _get_response
    response = wrapped_callback(request, *callback_args, **callback_kwargs)
  File "C:\Users\damia\Desktop\inge_software\punto_fitness\punto_app\views.py", line 33, in principal
    return render(request, 'punto_app/principal.html')
  File "C:\Users\damia\AppData\Local\Programs\Python\Python313\Lib\site-packages\django\shortcuts.py", line 25, in render
    content = loader.render_to_string(template_name, context, request, using=using)
  File "C:\Users\damia\AppData\Local\Programs\Python\Python313\Lib\site-packages\django\template\loader.py", line 62, in render_to_string
    return template.render(context, request)
           ~~~~~~~~~~~~~~~^^^^^^^^^^^^^^^^^^
  File "C:\Users\damia\AppData\Local\Programs\Python\Python313\Lib\site-packages\django\template\backends\django.py", line 107, in render
    return self.template.render(context)
           ~~~~~~~~~~~~~~~~~~~~^^^^^^^^^
  File "C:\Users\damia\AppData\Local\Programs\Python\Python313\Lib\site-packages\django\template\base.py", line 169, in render
    with context.bind_template(self):
         ~~~~~~~~~~~~~~~~~~~~~^^^^^^
  File "C:\Users\damia\AppData\Local\Programs\Python\Python313\Lib\contextlib.py", line 141, in __enter__
    return next(self.gen)
  File "C:\Users\damia\AppData\Local\Programs\Python\Python313\Lib\site-packages\django\template\context.py", line 259, in bind_template
    context = processor(self.request)
  File "C:\Users\damia\Desktop\inge_software\punto_fitness\punto_app\context_processors.py", line 4, in user_info
    cliente_id = request.session.get('cliente_id')
  File "C:\Users\damia\AppData\Local\Programs\Python\Python313\Lib\site-packages\django\contrib\sessions\backends\base.py", line 74, in get
    return self._session.get(key, default)
           ^^^^^^^^^^^^^
  File "C:\Users\damia\AppData\Local\Programs\Python\Python313\Lib\site-packages\django\contrib\sessions\backends\base.py", line 249, in _get_session
    self._session_cache = self.load()
                          ~~~~~~~~~^^
  File "C:\Users\damia\AppData\Local\Programs\Python\Python313\Lib\site-packages\django\contrib\sessions\backends\db.py", line 55, in load
    s = self._get_session_from_db()
  File "C:\Users\damia\AppData\Local\Programs\Python\Python313\Lib\site-packages\django\contrib\sessions\backends\db.py", line 34, in _get_session_from_db
    return self.model.objects.get(
           ~~~~~~~~~~~~~~~~~~~~~~^
        session_key=self.session_key, expire_date__gt=timezone.now()
        ^^^^^^^^^^^^^^^^^^^^^^^^^^^^^^^^^^^^^^^^^^^^^^^^^^^^^^^^^^^^
    )
    ^
  File "C:\Users\damia\AppData\Local\Programs\Python\Python313\Lib\site-packages\django\db\models\manager.py", line 87, in manager_method
    return getattr(self.get_queryset(), name)(*args, **kwargs)
           ~~~~~~~~~~~~~~~~~~~~~~~~~~~~~~~~~~^^^^^^^^^^^^^^^^^
  File "C:\Users\damia\AppData\Local\Programs\Python\Python313\Lib\site-packages\django\db\models\query.py", line 629, in get
    num = len(clone)
  File "C:\Users\damia\AppData\Local\Programs\Python\Python313\Lib\site-packages\django\db\models\query.py", line 366, in __len__
    self._fetch_all()
    ~~~~~~~~~~~~~~~^^
  File "C:\Users\damia\AppData\Local\Programs\Python\Python313\Lib\site-packages\django\db\models\query.py", line 1949, in _fetch_all
    self._result_cache = list(self._iterable_class(self))
                         ~~~~^^^^^^^^^^^^^^^^^^^^^^^^^^^^
  File "C:\Users\damia\AppData\Local\Programs\Python\Python313\Lib\site-packages\django\db\models\query.py", line 91, in __iter__
    results = compiler.execute_sql(
        chunked_fetch=self.chunked_fetch, chunk_size=self.chunk_size
    )
  File "C:\Users\damia\AppData\Local\Programs\Python\Python313\Lib\site-packages\django\db\models\sql\compiler.py", line 1623, in execute_sql
    cursor.execute(sql, params)
    ~~~~~~~~~~~~~~^^^^^^^^^^^^^
  File "C:\Users\damia\AppData\Local\Programs\Python\Python313\Lib\site-packages\django\db\backends\utils.py", line 122, in execute
    return super().execute(sql, params)
           ~~~~~~~~~~~~~~~^^^^^^^^^^^^^
  File "C:\Users\damia\AppData\Local\Programs\Python\Python313\Lib\site-packages\django\db\backends\utils.py", line 79, in execute
    return self._execute_with_wrappers(
           ~~~~~~~~~~~~~~~~~~~~~~~~~~~^
        sql, params, many=False, executor=self._execute
        ^^^^^^^^^^^^^^^^^^^^^^^^^^^^^^^^^^^^^^^^^^^^^^^
    )
    ^
  File "C:\Users\damia\AppData\Local\Programs\Python\Python313\Lib\site-packages\django\db\backends\utils.py", line 92, in _execute_with_wrappers
    return executor(sql, params, many, context)
  File "C:\Users\damia\AppData\Local\Programs\Python\Python313\Lib\site-packages\django\db\backends\utils.py", line 100, in _execute
    with self.db.wrap_database_errors:
         ^^^^^^^^^^^^^^^^^^^^^^^^^^^^
  File "C:\Users\damia\AppData\Local\Programs\Python\Python313\Lib\site-packages\django\db\utils.py", line 91, in __exit__
    raise dj_exc_value.with_traceback(traceback) from exc_value
  File "C:\Users\damia\AppData\Local\Programs\Python\Python313\Lib\site-packages\django\db\backends\utils.py", line 105, in _execute
    return self.cursor.execute(sql, params)
           ~~~~~~~~~~~~~~~~~~~^^^^^^^^^^^^^
django.db.utils.ProgrammingError: no existe la relación «django_session»
LINE 1: ...ession_data", "django_session"."expire_date" FROM "django_se...
                                                             ^

ERROR 2025-07-01 23:36:41,796 basehttp 13364 31904 "GET / HTTP/1.1" 500 181882
ERROR 2025-07-01 23:46:29,805 log 26104 33720 Internal Server Error: /venta_producto/
Traceback (most recent call last):
  File "C:\Users\damia\AppData\Local\Programs\Python\Python313\Lib\site-packages\django\template\base.py", line 891, in _resolve_lookup
    current = current[bit]
              ~~~~~~~^^^^^
  File "C:\Users\damia\AppData\Local\Programs\Python\Python313\Lib\site-packages\django\utils\functional.py", line 253, in inner
    return func(_wrapped, *args)
TypeError: 'AnonymousUser' object is not subscriptable

During handling of the above exception, another exception occurred:

Traceback (most recent call last):
  File "C:\Users\damia\AppData\Local\Programs\Python\Python313\Lib\site-packages\django\template\base.py", line 901, in _resolve_lookup
    current = getattr(current, bit)
  File "C:\Users\damia\AppData\Local\Programs\Python\Python313\Lib\site-packages\django\utils\functional.py", line 253, in inner
    return func(_wrapped, *args)
AttributeError: 'AnonymousUser' object has no attribute 'email'

During handling of the above exception, another exception occurred:

Traceback (most recent call last):
  File "C:\Users\damia\AppData\Local\Programs\Python\Python313\Lib\site-packages\django\template\base.py", line 907, in _resolve_lookup
    current = current[int(bit)]
                      ~~~^^^^^
ValueError: invalid literal for int() with base 10: 'email'

During handling of the above exception, another exception occurred:

Traceback (most recent call last):
  File "C:\Users\damia\AppData\Local\Programs\Python\Python313\Lib\site-packages\django\core\handlers\exception.py", line 55, in inner
    response = get_response(request)
  File "C:\Users\damia\AppData\Local\Programs\Python\Python313\Lib\site-packages\django\core\handlers\base.py", line 197, in _get_response
    response = wrapped_callback(request, *callback_args, **callback_kwargs)
  File "C:\Users\damia\Desktop\inge_software\punto_fitness\punto_app\views.py", line 2253, in venta_producto
    return render(request, 'punto_app/ventaproducto.html',{'productos': productos,'categorias': categorias})
  File "C:\Users\damia\AppData\Local\Programs\Python\Python313\Lib\site-packages\django\shortcuts.py", line 25, in render
    content = loader.render_to_string(template_name, context, request, using=using)
  File "C:\Users\damia\AppData\Local\Programs\Python\Python313\Lib\site-packages\django\template\loader.py", line 62, in render_to_string
    return template.render(context, request)
           ~~~~~~~~~~~~~~~^^^^^^^^^^^^^^^^^^
  File "C:\Users\damia\AppData\Local\Programs\Python\Python313\Lib\site-packages\django\template\backends\django.py", line 107, in render
    return self.template.render(context)
           ~~~~~~~~~~~~~~~~~~~~^^^^^^^^^
  File "C:\Users\damia\AppData\Local\Programs\Python\Python313\Lib\site-packages\django\template\base.py", line 171, in render
    return self._render(context)
           ~~~~~~~~~~~~^^^^^^^^^
  File "C:\Users\damia\AppData\Local\Programs\Python\Python313\Lib\site-packages\django\template\base.py", line 163, in _render
    return self.nodelist.render(context)
           ~~~~~~~~~~~~~~~~~~~~^^^^^^^^^
  File "C:\Users\damia\AppData\Local\Programs\Python\Python313\Lib\site-packages\django\template\base.py", line 1016, in render
    return SafeString("".join([node.render_annotated(context) for node in self]))
                               ~~~~~~~~~~~~~~~~~~~~~^^^^^^^^^
  File "C:\Users\damia\AppData\Local\Programs\Python\Python313\Lib\site-packages\django\template\base.py", line 977, in render_annotated
    return self.render(context)
           ~~~~~~~~~~~^^^^^^^^^
  File "C:\Users\damia\AppData\Local\Programs\Python\Python313\Lib\site-packages\django\template\loader_tags.py", line 159, in render
    return compiled_parent._render(context)
           ~~~~~~~~~~~~~~~~~~~~~~~^^^^^^^^^
  File "C:\Users\damia\AppData\Local\Programs\Python\Python313\Lib\site-packages\django\template\base.py", line 163, in _render
    return self.nodelist.render(context)
           ~~~~~~~~~~~~~~~~~~~~^^^^^^^^^
  File "C:\Users\damia\AppData\Local\Programs\Python\Python313\Lib\site-packages\django\template\base.py", line 1016, in render
    return SafeString("".join([node.render_annotated(context) for node in self]))
                               ~~~~~~~~~~~~~~~~~~~~~^^^^^^^^^
  File "C:\Users\damia\AppData\Local\Programs\Python\Python313\Lib\site-packages\django\template\base.py", line 977, in render_annotated
    return self.render(context)
           ~~~~~~~~~~~^^^^^^^^^
  File "C:\Users\damia\AppData\Local\Programs\Python\Python313\Lib\site-packages\django\template\base.py", line 1075, in render
    output = self.filter_expression.resolve(context)
  File "C:\Users\damia\AppData\Local\Programs\Python\Python313\Lib\site-packages\django\template\base.py", line 743, in resolve
    arg_vals.append(arg.resolve(context))
                    ~~~~~~~~~~~^^^^^^^^^
  File "C:\Users\damia\AppData\Local\Programs\Python\Python313\Lib\site-packages\django\template\base.py", line 854, in resolve
    value = self._resolve_lookup(context)
  File "C:\Users\damia\AppData\Local\Programs\Python\Python313\Lib\site-packages\django\template\base.py", line 914, in _resolve_lookup
    raise VariableDoesNotExist(
    ^^^^^^^^^^^^^^^^^^^^^^^^^^^
    ...<2 lines>...
    )  # missing attribute
    ^
django.template.base.VariableDoesNotExist: Failed lookup for key [email] in <SimpleLazyObject: <django.contrib.auth.models.AnonymousUser object at 0x0000015E686FC590>>
ERROR 2025-07-01 23:46:29,816 basehttp 26104 33720 "GET /venta_producto/ HTTP/1.1" 500 169146
ERROR 2025-07-02 04:04:39,404 log 28412 39548 Internal Server Error: /planes/
Traceback (most recent call last):
  File "C:\Users\damia\AppData\Local\Programs\Python\Python313\Lib\site-packages\django\core\handlers\exception.py", line 55, in inner
    response = get_response(request)
  File "C:\Users\damia\AppData\Local\Programs\Python\Python313\Lib\site-packages\django\core\handlers\base.py", line 197, in _get_response
    response = wrapped_callback(request, *callback_args, **callback_kwargs)
  File "C:\Users\damia\Desktop\inge_software\punto_fitness\punto_app\views.py", line 596, in planes
    planes=membresias.objects.values('id', 'nombre', 'descripcion', 'precio', 'duracion', 'imagen')
           ^^^^^^^^^^^^^^^^^^
AttributeError: 'function' object has no attribute 'objects'
ERROR 2025-07-02 04:04:39,407 basehttp 28412 39548 "GET /planes/ HTTP/1.1" 500 69363
